package aginsun.journey.worldgen;

import java.util.Random;

import net.minecraft.entity.Entity;
import net.minecraft.entity.item.EntityItem;
import net.minecraft.entity.player.EntityPlayer;
import net.minecraft.world.World;
import aginsun.journey.blocks.InitBlocks;
import cpw.mods.fml.common.FMLCommonHandler;

public class WorldGenGuild
{
    private World world = FMLCommonHandler.instance().getMinecraftServerInstance().worldServerForDimension(0);
    private WorldAddition world1;
    private Random rand;
    public static int i;
    public static int j;
    public static int k;
    EntityPlayer player;

    public WorldGenGuild(World world1, int l, int i1, int j1)
    {
        world = world1;
        i = l;
        j = i1;
        k = j1;
        rand = new Random();
    }

    public void CreateGuild()
    {
        for (int l = 0; l < 70; l++)
        {
            for (int l1 = 0; l1 < 90; l1++)
            {
                for (int k2 = 5; k2 < 90; k2++)
                {
                    world.setBlock(i + l, k + l1, j + k2, 0);
                }
            }
        }

        for (int i1 = 1; i1 < 7; i1++)
        {
            for (int i2 = -i1; i2 < 70 + i1; i2++)
            {
                for (int l2 = -i1; l2 < 90 + i1; l2++)
                {
                    int j3 = world.getBlockId(i + i2, k + i1, j + l2);
                    if (j3 == 18 || j3 == 17)
                    {
                        continue;
                    }
                    for (int k3 = 0; k3 < 20; k3++)
                    {
                        world.setBlock(i + i2, k + i1 + k3, j + l2, 0);
                    }
                }
            }
        }

        createPart0();
        createPart1();
        createPart2();
        createPart3();
        createPart4();
        createPart5();
        createPart6();
        createPart7();
        createPart8();
        createPart9();
        createPart10();
        createPart11();
        createPart12();
        createPart13();
        createPart14();
        createPart15();
        createPart16();
        createPart17();
        createPart18();
        createPart19();
        createPart20();
        createPart21();
        for (int j1 = 0; j1 < 80; j1++)
        {
            for (int j2 = 0; j2 < 100; j2++)
            {
                int i3 = world.getBlockId(i + j1, k, j + j2);
                if (i3 == 2 || i3 == 3 || i3 == 13)
                {
                    world.setBlock(i + j1, k - 1, j + j2, 3);
                    world.setBlock(i + j1, k - 2, j + j2, 3);
                    world.setBlock(i + j1, k - 3, j + j2, 3);
                    world.setBlock(i + j1, k - 4, j + j2, 3);
                    world.setBlock(i + j1, k - 5, j + j2, 3);
                    world.setBlock(i + j1, k - 6, j + j2, 3);
                    world.setBlock(i + j1, k - 7, j + j2, 3);
                    world.setBlock(i + j1, k - 8, j + j2, 3);
                    world.setBlock(i + j1, k - 9, j + j2, 3);
                    world.setBlock(i + j1, k - 10, j + j2, 3);
                    world.setBlock(i + j1, k - 11, j + j2, 3);
                    world.setBlock(i + j1, k - 12, j + j2, 3);
                    world.setBlock(i + j1, k - 13, j + j2, 3);
                    world.setBlock(i + j1, k - 14, j + j2, 3);
                    world.setBlock(i + j1, k - 15, j + j2, 3);
                }
            }
        }

        if (!world.loadedEntityList.isEmpty())
        {
            for (int k1 = 0; k1 < world.loadedEntityList.size(); k1++)
            {
                Entity entity = (Entity)world.loadedEntityList.get(k1);
                if (entity instanceof EntityItem)
                {
                    EntityItem entityitem = (EntityItem)entity;
                    entityitem.setDead();
                }
            }
        }
    }

    private void createPart0()
    {
        world.setBlock(i + 0, k + 0, j + 5, 2);
        world.setBlock(i + 0, k + 0, j + 6, 2);
        world.setBlock(i + 0, k + 0, j + 7, 2);
        world.setBlock(i + 0, k + 0, j + 8, 2);
        world.setBlock(i + 0, k + 0, j + 9, 2);
        world.setBlock(i + 0, k + 0, j + 10, 2);
        world.setBlock(i + 0, k + 0, j + 11, 2);
        world.setBlock(i + 0, k + 0, j + 12, 2);
        world.setBlock(i + 0, k + 0, j + 13, 2);
        world.setBlock(i + 0, k + 0, j + 14, 2);
        world.setBlock(i + 0, k + 0, j + 15, 2);
        world.setBlock(i + 0, k + 0, j + 19, 2);
        world.setBlock(i + 0, k + 0, j + 20, 2);
        world.setBlock(i + 0, k + 0, j + 21, 2);
        world.setBlock(i + 0, k + 0, j + 22, 2);
        world.setBlock(i + 0, k + 0, j + 23, 2);
        world.setBlock(i + 0, k + 0, j + 24, 3);
        world.setBlock(i + 0, k + 0, j + 25, 3);
        world.setBlock(i + 0, k + 0, j + 26, 3);
        world.setBlock(i + 0, k + 0, j + 27, 2);
        world.setBlock(i + 0, k + 0, j + 28, 2);
        world.setBlock(i + 0, k + 0, j + 32, 2);
        world.setBlock(i + 0, k + 0, j + 33, 2);
        world.setBlock(i + 0, k + 0, j + 34, 2);
        world.setBlock(i + 0, k + 0, j + 35, 2);
        world.setBlock(i + 0, k + 0, j + 36, 2);
        world.setBlock(i + 0, k + 0, j + 37, 2);
        world.setBlock(i + 0, k + 0, j + 38, 2);
        world.setBlock(i + 0, k + 0, j + 39, 2);
        world.setBlock(i + 0, k + 0, j + 40, 2);
        world.setBlock(i + 0, k + 0, j + 41, 2);
        world.setBlock(i + 0, k + 0, j + 42, 2);
        world.setBlock(i + 0, k + 0, j + 43, 3);
        world.setBlock(i + 0, k + 0, j + 44, 2);
        world.setBlock(i + 0, k + 0, j + 45, 2);
        world.setBlock(i + 0, k + 0, j + 46, 2);
        world.setBlock(i + 0, k + 0, j + 47, 3);
        world.setBlock(i + 0, k + 0, j + 48, 3);
        world.setBlock(i + 0, k + 0, j + 49, 3);
        world.setBlock(i + 0, k + 0, j + 50, 3);
        world.setBlock(i + 0, k + 0, j + 51, 3);
        world.setBlock(i + 0, k + 0, j + 52, 3);
        world.setBlock(i + 0, k + 0, j + 53, 3);
        world.setBlock(i + 0, k + 0, j + 54, 3);
        world.setBlock(i + 0, k + 0, j + 55, 3);
        world.setBlock(i + 0, k + 0, j + 56, 3);
        world.setBlock(i + 0, k + 0, j + 57, 3);
        world.setBlock(i + 0, k + 0, j + 58, 2);
        world.setBlock(i + 0, k + 0, j + 59, 2);
        world.setBlock(i + 0, k + 0, j + 60, 2);
        world.setBlock(i + 0, k + 0, j + 61, 2);
        world.setBlock(i + 0, k + 0, j + 62, 2);
        world.setBlock(i + 0, k + 0, j + 63, 2);
        world.setBlock(i + 0, k + 0, j + 64, 2);
        world.setBlock(i + 0, k + 0, j + 65, 3);
        world.setBlock(i + 0, k + 0, j + 66, 3);
        world.setBlock(i + 0, k + 0, j + 67, 2);
        world.setBlock(i + 0, k + 0, j + 68, 2);
        world.setBlock(i + 0, k + 0, j + 75, 2);
        world.setBlock(i + 0, k + 0, j + 76, 2);
        world.setBlock(i + 0, k + 0, j + 77, 2);
        world.setBlock(i + 0, k + 0, j + 78, 2);
        world.setBlock(i + 0, k + 0, j + 79, 2);
        world.setBlock(i + 0, k + 0, j + 80, 2);
        world.setBlock(i + 0, k + 0, j + 81, 2);
        world.setBlock(i + 0, k + 0, j + 84, 2);
        world.setBlock(i + 0, k + 0, j + 85, 2);
        world.setBlock(i + 0, k + 1, j + 24, 2);
        world.setBlock(i + 0, k + 1, j + 25, 2);
        world.setBlock(i + 0, k + 1, j + 26, 2);
        world.setBlock(i + 0, k + 1, j + 43, 2);
        world.setBlock(i + 0, k + 1, j + 47, 2);
        world.setBlock(i + 0, k + 1, j + 48, 2);
        world.setBlock(i + 0, k + 1, j + 49, 2);
        world.setBlock(i + 0, k + 1, j + 50, 2);
        world.setBlock(i + 0, k + 1, j + 51, 2);
        world.setBlock(i + 0, k + 1, j + 52, 2);
        world.setBlock(i + 0, k + 1, j + 53, 2);
        world.setBlock(i + 0, k + 1, j + 54, 2);
        world.setBlock(i + 0, k + 1, j + 55, 2);
        world.setBlock(i + 0, k + 1, j + 56, 2);
        world.setBlock(i + 0, k + 1, j + 57, 2);
        world.setBlock(i + 0, k + 1, j + 65, 2);
        world.setBlock(i + 0, k + 1, j + 66, 2);
        world.setBlock(i + 1, k + 0, j + 2, 13);
        world.setBlock(i + 1, k + 0, j + 3, 13);
        world.setBlock(i + 1, k + 0, j + 4, 13);
        world.setBlock(i + 1, k + 0, j + 5, 13);
        world.setBlock(i + 1, k + 0, j + 6, 13);
        world.setBlock(i + 1, k + 0, j + 7, 13);
        world.setBlock(i + 1, k + 0, j + 8, 13);
        world.setBlock(i + 1, k + 0, j + 9, 13);
        world.setBlock(i + 1, k + 0, j + 10, 13);
        world.setBlock(i + 1, k + 0, j + 11, 13);
        world.setBlock(i + 1, k + 0, j + 12, 13);
        world.setBlock(i + 1, k + 0, j + 13, 13);
        world.setBlock(i + 1, k + 0, j + 14, 13);
        world.setBlock(i + 1, k + 0, j + 15, 13);
        world.setBlock(i + 1, k + 0, j + 16, 13);
        world.setBlock(i + 1, k + 0, j + 17, 13);
        world.setBlock(i + 1, k + 0, j + 18, 13);
        world.setBlock(i + 1, k + 0, j + 19, 13);
        world.setBlock(i + 1, k + 0, j + 20, 13);
        world.setBlock(i + 1, k + 0, j + 21, 13);
        world.setBlock(i + 1, k + 0, j + 22, 13);
        world.setBlock(i + 1, k + 0, j + 23, 13);
        world.setBlock(i + 1, k + 0, j + 24, 13);
        world.setBlock(i + 1, k + 0, j + 25, 13);
        world.setBlock(i + 1, k + 0, j + 26, 13);
        world.setBlock(i + 1, k + 0, j + 27, 13);
        world.setBlock(i + 1, k + 0, j + 28, 13);
        world.setBlock(i + 1, k + 0, j + 29, 13);
        world.setBlock(i + 1, k + 0, j + 30, 13);
        world.setBlock(i + 1, k + 0, j + 31, 13);
        world.setBlock(i + 1, k + 0, j + 32, 13);
        world.setBlock(i + 1, k + 0, j + 33, 13);
        world.setBlock(i + 1, k + 0, j + 34, 13);
        world.setBlock(i + 1, k + 0, j + 35, 13);
        world.setBlock(i + 1, k + 0, j + 36, 13);
        world.setBlock(i + 1, k + 0, j + 37, 13);
        world.setBlock(i + 1, k + 0, j + 38, 13);
        world.setBlock(i + 1, k + 0, j + 39, 13);
        world.setBlock(i + 1, k + 0, j + 40, 13);
        world.setBlock(i + 1, k + 0, j + 41, 13);
        world.setBlock(i + 1, k + 0, j + 42, 3);
        world.setBlock(i + 1, k + 0, j + 43, 3);
        world.setBlock(i + 1, k + 0, j + 44, 3);
        world.setBlock(i + 1, k + 0, j + 45, 3);
        world.setBlock(i + 1, k + 0, j + 46, 3);
        world.setBlock(i + 1, k + 0, j + 47, 3);
        world.setBlock(i + 1, k + 0, j + 48, 3);
        world.setBlock(i + 1, k + 0, j + 49, 3);
        world.setBlock(i + 1, k + 0, j + 50, 3);
        world.setBlock(i + 1, k + 0, j + 51, 3);
        world.setBlock(i + 1, k + 0, j + 52, 13);
        world.setBlock(i + 1, k + 0, j + 53, 13);
        world.setBlock(i + 1, k + 0, j + 54, 13);
        world.setBlock(i + 1, k + 0, j + 55, 13);
        world.setBlock(i + 1, k + 0, j + 56, 13);
        world.setBlock(i + 1, k + 0, j + 57, 13);
        world.setBlock(i + 1, k + 0, j + 58, 3);
        world.setBlock(i + 1, k + 0, j + 59, 3);
        world.setBlock(i + 1, k + 0, j + 60, 3);
        world.setBlock(i + 1, k + 0, j + 61, 3);
        world.setBlock(i + 1, k + 0, j + 62, 3);
        world.setBlock(i + 1, k + 0, j + 63, 3);
        world.setBlock(i + 1, k + 0, j + 64, 3);
        world.setBlock(i + 1, k + 0, j + 65, 3);
        world.setBlock(i + 1, k + 0, j + 66, 3);
        world.setBlock(i + 1, k + 0, j + 67, 3);
        world.setBlock(i + 1, k + 0, j + 68, 2);
        world.setBlock(i + 1, k + 0, j + 69, 2);
        world.setBlock(i + 1, k + 0, j + 70, 2);
        world.setBlock(i + 1, k + 0, j + 71, 2);
        world.setBlock(i + 1, k + 0, j + 72, 2);
        world.setBlock(i + 1, k + 0, j + 73, 2);
        world.setBlock(i + 1, k + 0, j + 74, 2);
        world.setBlock(i + 1, k + 0, j + 75, 2);
        world.setBlock(i + 1, k + 0, j + 76, 3);
        world.setBlock(i + 1, k + 0, j + 77, 2);
        world.setBlock(i + 1, k + 0, j + 78, 3);
        world.setBlock(i + 1, k + 0, j + 79, 3);
        world.setBlock(i + 1, k + 0, j + 80, 3);
        world.setBlock(i + 1, k + 0, j + 81, 2);
        world.setBlock(i + 1, k + 0, j + 82, 2);
        world.setBlock(i + 1, k + 0, j + 83, 2);
        world.setBlock(i + 1, k + 0, j + 84, 3);
        world.setBlock(i + 1, k + 0, j + 85, 3);
        world.setBlock(i + 1, k + 0, j + 86, 2);
        world.setBlock(i + 1, k + 0, j + 87, 2);
        world.setBlock(i + 1, k + 0, j + 88, 2);
        world.setBlock(i + 1, k + 1, j + 42, 13);
        world.setBlock(i + 1, k + 1, j + 43, 13);
        world.setBlock(i + 1, k + 1, j + 44, 13);
        world.setBlock(i + 1, k + 1, j + 45, 13);
        world.setBlock(i + 1, k + 1, j + 46, 13);
        world.setBlock(i + 1, k + 1, j + 47, 13);
        world.setBlock(i + 1, k + 1, j + 48, 13);
        world.setBlock(i + 1, k + 1, j + 49, 13);
        world.setBlock(i + 1, k + 1, j + 50, 13);
        world.setBlock(i + 1, k + 1, j + 51, 13);
        world.setBlock(i + 1, k + 1, j + 52, 13);
        world.setBlock(i + 1, k + 1, j + 53, 13);
        world.setBlock(i + 1, k + 1, j + 54, 13);
        world.setBlock(i + 1, k + 1, j + 55, 13);
        world.setBlock(i + 1, k + 1, j + 56, 13);
        world.setBlock(i + 1, k + 1, j + 57, 2);
        world.setBlock(i + 1, k + 1, j + 58, 2);
        world.setBlock(i + 1, k + 1, j + 59, 2);
        world.setBlock(i + 1, k + 1, j + 60, 2);
        world.setBlock(i + 1, k + 1, j + 61, 2);
        world.setBlock(i + 1, k + 1, j + 62, 2);
        world.setBlock(i + 1, k + 1, j + 63, 2);
        world.setBlock(i + 1, k + 1, j + 64, 2);
        world.setBlock(i + 1, k + 1, j + 65, 2);
        world.setBlock(i + 1, k + 1, j + 66, 2);
        world.setBlock(i + 1, k + 1, j + 67, 2);
        world.setBlock(i + 1, k + 1, j + 76, 2);
        world.setBlock(i + 1, k + 1, j + 78, 2);
        world.setBlock(i + 1, k + 1, j + 79, 2);
        world.setBlock(i + 1, k + 1, j + 80, 2);
        world.setBlock(i + 1, k + 1, j + 84, 2);
        world.setBlock(i + 1, k + 1, j + 85, 2);
        world1.setBlockWithMetadata(i + 1, k + 2, j + 60, 31, 1);
        world1.setBlockWithMetadata(i + 1, k + 2, j + 61, 31, 1);
        world1.setBlockWithMetadata(i + 1, k + 2, j + 62, 31, 1);
        world.setBlock(i + 1, k + 2, j + 76, 37);
        world1.setBlockWithMetadata(i + 1, k + 2, j + 79, 31, 1);
        world.setBlock(i + 1, k + 4, j + 67, 18);
        world.setBlock(i + 1, k + 4, j + 68, 18);
        world.setBlock(i + 1, k + 4, j + 69, 18);
        world.setBlock(i + 1, k + 4, j + 70, 18);
        world.setBlock(i + 1, k + 5, j + 68, 18);
        world.setBlock(i + 1, k + 5, j + 69, 18);
        world.setBlock(i + 1, k + 5, j + 70, 18);
        world.setBlock(i + 1, k + 5, j + 71, 18);
        world.setBlock(i + 2, k + 0, j + 2, 13);
        world.setBlock(i + 2, k + 0, j + 3, 13);
        world.setBlock(i + 2, k + 0, j + 4, 13);
        world.setBlock(i + 2, k + 0, j + 5, 13);
        world.setBlock(i + 2, k + 0, j + 6, 13);
        world.setBlock(i + 2, k + 0, j + 7, 13);
        world.setBlock(i + 2, k + 0, j + 8, 13);
        world.setBlock(i + 2, k + 0, j + 9, 13);
        world.setBlock(i + 2, k + 0, j + 10, 13);
        world.setBlock(i + 2, k + 0, j + 11, 13);
        world.setBlock(i + 2, k + 0, j + 12, 13);
        world.setBlock(i + 2, k + 0, j + 13, 13);
        world.setBlock(i + 2, k + 0, j + 14, 13);
        world.setBlock(i + 2, k + 0, j + 15, 13);
        world.setBlock(i + 2, k + 0, j + 16, 13);
        world.setBlock(i + 2, k + 0, j + 17, 13);
        world.setBlock(i + 2, k + 0, j + 18, 13);
        world.setBlock(i + 2, k + 0, j + 19, 13);
        world.setBlock(i + 2, k + 0, j + 20, 13);
        world.setBlock(i + 2, k + 0, j + 21, 13);
        world.setBlock(i + 2, k + 0, j + 22, 13);
        world.setBlock(i + 2, k + 0, j + 23, 13);
        world.setBlock(i + 2, k + 0, j + 24, 13);
        world.setBlock(i + 2, k + 0, j + 25, 13);
        world.setBlock(i + 2, k + 0, j + 26, 13);
        world.setBlock(i + 2, k + 0, j + 27, 13);
        world.setBlock(i + 2, k + 0, j + 28, 13);
        world.setBlock(i + 2, k + 0, j + 29, 13);
        world.setBlock(i + 2, k + 0, j + 30, 13);
        world.setBlock(i + 2, k + 0, j + 31, 13);
        world.setBlock(i + 2, k + 0, j + 32, 13);
        world.setBlock(i + 2, k + 0, j + 33, 13);
        world.setBlock(i + 2, k + 0, j + 34, 13);
        world.setBlock(i + 2, k + 0, j + 35, 13);
        world.setBlock(i + 2, k + 0, j + 36, 13);
        world.setBlock(i + 2, k + 0, j + 37, 13);
        world.setBlock(i + 2, k + 0, j + 38, 13);
        world.setBlock(i + 2, k + 0, j + 39, 13);
        world.setBlock(i + 2, k + 0, j + 40, 13);
        world.setBlock(i + 2, k + 0, j + 41, 13);
        world.setBlock(i + 2, k + 0, j + 42, 3);
        world.setBlock(i + 2, k + 0, j + 43, 3);
        world.setBlock(i + 2, k + 0, j + 44, 3);
        world.setBlock(i + 2, k + 0, j + 45, 3);
        world.setBlock(i + 2, k + 0, j + 46, 3);
        world.setBlock(i + 2, k + 0, j + 47, 3);
        world.setBlock(i + 2, k + 0, j + 48, 3);
        world.setBlock(i + 2, k + 0, j + 49, 3);
        world.setBlock(i + 2, k + 0, j + 50, 3);
        world.setBlock(i + 2, k + 0, j + 51, 3);
        world.setBlock(i + 2, k + 0, j + 52, 13);
        world.setBlock(i + 2, k + 0, j + 53, 13);
        world.setBlock(i + 2, k + 0, j + 54, 13);
        world.setBlock(i + 2, k + 0, j + 55, 13);
        world.setBlock(i + 2, k + 0, j + 56, 13);
        world.setBlock(i + 2, k + 0, j + 57, 13);
        world.setBlock(i + 2, k + 0, j + 58, 3);
        world.setBlock(i + 2, k + 0, j + 59, 3);
        world.setBlock(i + 2, k + 0, j + 60, 3);
        world.setBlock(i + 2, k + 0, j + 61, 3);
        world.setBlock(i + 2, k + 0, j + 62, 3);
        world.setBlock(i + 2, k + 0, j + 63, 3);
        world.setBlock(i + 2, k + 0, j + 64, 3);
        world.setBlock(i + 2, k + 0, j + 65, 3);
        world.setBlock(i + 2, k + 0, j + 66, 3);
        world.setBlock(i + 2, k + 0, j + 67, 3);
        world.setBlock(i + 2, k + 0, j + 68, 3);
        world.setBlock(i + 2, k + 0, j + 69, 2);
        world.setBlock(i + 2, k + 0, j + 70, 3);
        world.setBlock(i + 2, k + 0, j + 71, 3);
        world.setBlock(i + 2, k + 0, j + 72, 3);
        world.setBlock(i + 2, k + 0, j + 73, 3);
        world.setBlock(i + 2, k + 0, j + 74, 3);
        world.setBlock(i + 2, k + 0, j + 75, 2);
        world.setBlock(i + 2, k + 0, j + 76, 3);
        world.setBlock(i + 2, k + 0, j + 77, 3);
        world.setBlock(i + 2, k + 0, j + 78, 3);
        world.setBlock(i + 2, k + 0, j + 79, 3);
        world.setBlock(i + 2, k + 0, j + 80, 3);
        world.setBlock(i + 2, k + 0, j + 81, 2);
        world.setBlock(i + 2, k + 0, j + 82, 3);
        world.setBlock(i + 2, k + 0, j + 83, 3);
        world.setBlock(i + 2, k + 0, j + 84, 3);
        world.setBlock(i + 2, k + 0, j + 85, 3);
        world.setBlock(i + 2, k + 0, j + 86, 3);
        world.setBlock(i + 2, k + 0, j + 87, 3);
        world.setBlock(i + 2, k + 0, j + 88, 3);
        world.setBlock(i + 2, k + 0, j + 89, 2);
        world.setBlock(i + 2, k + 1, j + 42, 13);
        world.setBlock(i + 2, k + 1, j + 43, 13);
        world.setBlock(i + 2, k + 1, j + 44, 13);
        world.setBlock(i + 2, k + 1, j + 45, 13);
        world.setBlock(i + 2, k + 1, j + 46, 13);
        world.setBlock(i + 2, k + 1, j + 47, 13);
        world.setBlock(i + 2, k + 1, j + 48, 13);
        world.setBlock(i + 2, k + 1, j + 49, 13);
        world.setBlock(i + 2, k + 1, j + 50, 13);
        world.setBlock(i + 2, k + 1, j + 51, 13);
        world.setBlock(i + 2, k + 1, j + 52, 13);
        world.setBlock(i + 2, k + 1, j + 53, 13);
        world.setBlock(i + 2, k + 1, j + 54, 13);
        world.setBlock(i + 2, k + 1, j + 55, 13);
        world.setBlock(i + 2, k + 1, j + 56, 13);
        world.setBlock(i + 2, k + 1, j + 57, 13);
        world.setBlock(i + 2, k + 1, j + 58, 2);
        world.setBlock(i + 2, k + 1, j + 59, 2);
        world.setBlock(i + 2, k + 1, j + 60, 2);
        world.setBlock(i + 2, k + 1, j + 61, 2);
        world.setBlock(i + 2, k + 1, j + 62, 2);
        world.setBlock(i + 2, k + 1, j + 63, 2);
        world.setBlock(i + 2, k + 1, j + 64, 2);
        world.setBlock(i + 2, k + 1, j + 65, 2);
        world.setBlock(i + 2, k + 1, j + 66, 2);
        world.setBlock(i + 2, k + 1, j + 67, 2);
        world.setBlock(i + 2, k + 1, j + 68, 2);
        world.setBlock(i + 2, k + 1, j + 70, 2);
        world.setBlock(i + 2, k + 1, j + 71, 2);
        world.setBlock(i + 2, k + 1, j + 72, 2);
        world.setBlock(i + 2, k + 1, j + 73, 2);
        world.setBlock(i + 2, k + 1, j + 74, 2);
        world.setBlock(i + 2, k + 1, j + 76, 2);
        world.setBlock(i + 2, k + 1, j + 77, 2);
        world.setBlock(i + 2, k + 1, j + 78, 2);
        world.setBlock(i + 2, k + 1, j + 79, 2);
        world.setBlock(i + 2, k + 1, j + 80, 2);
        world.setBlock(i + 2, k + 1, j + 82, 2);
        world.setBlock(i + 2, k + 1, j + 83, 2);
        world.setBlock(i + 2, k + 1, j + 84, 2);
        world.setBlock(i + 2, k + 1, j + 85, 2);
        world.setBlock(i + 2, k + 1, j + 86, 2);
        world.setBlock(i + 2, k + 1, j + 87, 2);
        world.setBlock(i + 2, k + 1, j + 88, 2);
        world1.setBlockWithMetadata(i + 2, k + 2, j + 59, 31, 1);
        world1.setBlockWithMetadata(i + 2, k + 2, j + 60, 31, 1);
        world1.setBlockWithMetadata(i + 2, k + 2, j + 61, 31, 1);
        world1.setBlockWithMetadata(i + 2, k + 2, j + 62, 31, 1);
        world1.setBlockWithMetadata(i + 2, k + 2, j + 63, 31, 1);
        world1.setBlockWithMetadata(i + 2, k + 2, j + 64, 31, 1);
        world1.setBlockWithMetadata(i + 2, k + 2, j + 65, 31, 1);
        world1.setBlockWithMetadata(i + 2, k + 2, j + 66, 31, 1);
        world1.setBlockWithMetadata(i + 2, k + 2, j + 67, 31, 1);
        world1.setBlockWithMetadata(i + 2, k + 2, j + 70, 31, 1);
        world1.setBlockWithMetadata(i + 2, k + 2, j + 71, 31, 1);
        world1.setBlockWithMetadata(i + 2, k + 2, j + 73, 31, 1);
        world1.setBlockWithMetadata(i + 2, k + 2, j + 74, 31, 1);
        world1.setBlockWithMetadata(i + 2, k + 2, j + 78, 31, 1);
        world1.setBlockWithMetadata(i + 2, k + 2, j + 79, 31, 1);
        world1.setBlockWithMetadata(i + 2, k + 2, j + 80, 31, 1);
        world.setBlock(i + 2, k + 4, j + 67, 18);
        world.setBlock(i + 2, k + 4, j + 68, 18);
        world.setBlock(i + 2, k + 4, j + 69, 18);
        world.setBlock(i + 2, k + 4, j + 70, 18);
        world.setBlock(i + 2, k + 4, j + 71, 18);
        world.setBlock(i + 2, k + 5, j + 67, 18);
        world.setBlock(i + 2, k + 5, j + 68, 18);
        world.setBlock(i + 2, k + 5, j + 69, 18);
        world.setBlock(i + 2, k + 5, j + 70, 18);
        world.setBlock(i + 2, k + 5, j + 71, 18);
        world.setBlock(i + 2, k + 6, j + 68, 18);
        world.setBlock(i + 2, k + 6, j + 69, 18);
        world.setBlock(i + 2, k + 6, j + 70, 18);
        world.setBlock(i + 2, k + 7, j + 69, 18);
        world.setBlock(i + 3, k + 0, j + 2, 2);
        world.setBlock(i + 3, k + 0, j + 3, 2);
        world.setBlock(i + 3, k + 0, j + 4, 2);
        world.setBlock(i + 3, k + 0, j + 5, 2);
        world.setBlock(i + 3, k + 0, j + 6, 2);
        world.setBlock(i + 3, k + 0, j + 7, 2);
        world.setBlock(i + 3, k + 0, j + 8, 2);
        world.setBlock(i + 3, k + 0, j + 9, 2);
        world.setBlock(i + 3, k + 0, j + 10, 2);
        world.setBlock(i + 3, k + 0, j + 11, 2);
        world.setBlock(i + 3, k + 0, j + 12, 2);
        world.setBlock(i + 3, k + 0, j + 13, 2);
        world.setBlock(i + 3, k + 0, j + 14, 2);
        world.setBlock(i + 3, k + 0, j + 15, 2);
        world.setBlock(i + 3, k + 0, j + 16, 2);
        world.setBlock(i + 3, k + 0, j + 17, 2);
        world.setBlock(i + 3, k + 0, j + 18, 2);
        world.setBlock(i + 3, k + 0, j + 19, 2);
        world.setBlock(i + 3, k + 0, j + 20, 2);
        world.setBlock(i + 3, k + 0, j + 21, 2);
        world.setBlock(i + 3, k + 0, j + 22, 2);
        world.setBlock(i + 3, k + 0, j + 23, 2);
        world.setBlock(i + 3, k + 0, j + 24, 2);
        world.setBlock(i + 3, k + 0, j + 25, 2);
        world.setBlock(i + 3, k + 0, j + 26, 2);
        world.setBlock(i + 3, k + 0, j + 27, 2);
        world.setBlock(i + 3, k + 0, j + 28, 3);
        world.setBlock(i + 3, k + 0, j + 29, 3);
        world.setBlock(i + 3, k + 0, j + 30, 2);
        world.setBlock(i + 3, k + 0, j + 31, 3);
        world.setBlock(i + 3, k + 0, j + 32, 2);
        world.setBlock(i + 3, k + 0, j + 33, 3);
        world.setBlock(i + 3, k + 0, j + 34, 3);
        world.setBlock(i + 3, k + 0, j + 35, 3);
        world.setBlock(i + 3, k + 0, j + 36, 3);
        world.setBlock(i + 3, k + 0, j + 37, 3);
        world.setBlock(i + 3, k + 0, j + 38, 3);
        world.setBlock(i + 3, k + 0, j + 39, 2);
        world.setBlock(i + 3, k + 0, j + 40, 2);
        world.setBlock(i + 3, k + 0, j + 41, 2);
        world.setBlock(i + 3, k + 0, j + 42, 2);
        world.setBlock(i + 3, k + 0, j + 43, 3);
        world.setBlock(i + 3, k + 0, j + 44, 3);
        world.setBlock(i + 3, k + 0, j + 45, 3);
        world.setBlock(i + 3, k + 0, j + 46, 3);
        world.setBlock(i + 3, k + 0, j + 47, 3);
        world.setBlock(i + 3, k + 0, j + 48, 3);
        world.setBlock(i + 3, k + 0, j + 49, 3);
        world.setBlock(i + 3, k + 0, j + 50, 3);
        world.setBlock(i + 3, k + 0, j + 51, 13);
        world.setBlock(i + 3, k + 0, j + 52, 13);
        world.setBlock(i + 3, k + 0, j + 53, 13);
        world.setBlock(i + 3, k + 0, j + 54, 13);
        world.setBlock(i + 3, k + 0, j + 55, 13);
        world.setBlock(i + 3, k + 0, j + 56, 13);
        world.setBlock(i + 3, k + 0, j + 57, 13);
        world.setBlock(i + 3, k + 0, j + 58, 13);
        world.setBlock(i + 3, k + 0, j + 59, 3);
        world.setBlock(i + 3, k + 0, j + 60, 3);
        world.setBlock(i + 3, k + 0, j + 61, 3);
        world.setBlock(i + 3, k + 0, j + 62, 3);
        world.setBlock(i + 3, k + 0, j + 63, 3);
        world.setBlock(i + 3, k + 0, j + 64, 3);
        world.setBlock(i + 3, k + 0, j + 65, 3);
        world.setBlock(i + 3, k + 0, j + 66, 3);
        world.setBlock(i + 3, k + 0, j + 67, 3);
        world.setBlock(i + 3, k + 0, j + 68, 3);
        world.setBlock(i + 3, k + 0, j + 69, 3);
        world.setBlock(i + 3, k + 0, j + 70, 3);
        world.setBlock(i + 3, k + 0, j + 71, 3);
        world.setBlock(i + 3, k + 0, j + 72, 3);
        world.setBlock(i + 3, k + 0, j + 73, 3);
        world.setBlock(i + 3, k + 0, j + 74, 3);
        world.setBlock(i + 3, k + 0, j + 75, 3);
        world.setBlock(i + 3, k + 0, j + 76, 3);
        world.setBlock(i + 3, k + 0, j + 77, 3);
        world.setBlock(i + 3, k + 0, j + 78, 3);
        world.setBlock(i + 3, k + 0, j + 79, 3);
        world.setBlock(i + 3, k + 0, j + 80, 3);
        world.setBlock(i + 3, k + 0, j + 81, 3);
        world.setBlock(i + 3, k + 0, j + 82, 3);
        world.setBlock(i + 3, k + 0, j + 83, 3);
        world.setBlock(i + 3, k + 0, j + 84, 3);
        world.setBlock(i + 3, k + 0, j + 85, 3);
        world.setBlock(i + 3, k + 0, j + 86, 3);
        world.setBlock(i + 3, k + 0, j + 87, 3);
        world.setBlock(i + 3, k + 0, j + 88, 3);
        world.setBlock(i + 3, k + 0, j + 89, 2);
        world1.setBlockWithMetadata(i + 3, k + 1, j + 9, 31, 1);
        world1.setBlockWithMetadata(i + 3, k + 1, j + 10, 31, 1);
        world.setBlock(i + 3, k + 1, j + 11, 38);
        world1.setBlockWithMetadata(i + 3, k + 1, j + 12, 31, 1);
        world1.setBlockWithMetadata(i + 3, k + 1, j + 22, 31, 1);
        world.setBlock(i + 3, k + 1, j + 25, 38);
        world1.setBlockWithMetadata(i + 3, k + 1, j + 26, 31, 1);
        world.setBlock(i + 3, k + 1, j + 28, 2);
        world.setBlock(i + 3, k + 1, j + 29, 2);
        world.setBlock(i + 3, k + 1, j + 31, 2);
        world.setBlock(i + 3, k + 1, j + 33, 2);
        world.setBlock(i + 3, k + 1, j + 34, 2);
        world.setBlock(i + 3, k + 1, j + 35, 2);
        world.setBlock(i + 3, k + 1, j + 36, 2);
        world.setBlock(i + 3, k + 1, j + 37, 2);
        world.setBlock(i + 3, k + 1, j + 38, 2);
        world.setBlock(i + 3, k + 1, j + 43, 2);
        world.setBlock(i + 3, k + 1, j + 44, 2);
        world.setBlock(i + 3, k + 1, j + 45, 2);
        world.setBlock(i + 3, k + 1, j + 46, 2);
        world.setBlock(i + 3, k + 1, j + 47, 2);
        world.setBlock(i + 3, k + 1, j + 48, 2);
        world.setBlock(i + 3, k + 1, j + 49, 2);
        world.setBlock(i + 3, k + 1, j + 50, 2);
        world.setBlock(i + 3, k + 1, j + 51, 13);
        world.setBlock(i + 3, k + 1, j + 52, 13);
        world.setBlock(i + 3, k + 1, j + 53, 13);
        world.setBlock(i + 3, k + 1, j + 54, 13);
        world.setBlock(i + 3, k + 1, j + 55, 13);
        world.setBlock(i + 3, k + 1, j + 56, 13);
        world.setBlock(i + 3, k + 1, j + 57, 13);
        world.setBlock(i + 3, k + 1, j + 58, 13);
        world.setBlock(i + 3, k + 1, j + 59, 2);
        world.setBlock(i + 3, k + 1, j + 60, 2);
        world.setBlock(i + 3, k + 1, j + 61, 2);
        world.setBlock(i + 3, k + 1, j + 62, 2);
        world.setBlock(i + 3, k + 1, j + 63, 2);
        world.setBlock(i + 3, k + 1, j + 64, 2);
        world.setBlock(i + 3, k + 1, j + 65, 2);
        world.setBlock(i + 3, k + 1, j + 66, 2);
        world.setBlock(i + 3, k + 1, j + 67, 2);
        world.setBlock(i + 3, k + 1, j + 68, 2);
        world.setBlock(i + 3, k + 1, j + 69, 3);
        world.setBlock(i + 3, k + 1, j + 70, 2);
        world.setBlock(i + 3, k + 1, j + 71, 2);
        world.setBlock(i + 3, k + 1, j + 72, 2);
        world.setBlock(i + 3, k + 1, j + 73, 2);
        world.setBlock(i + 3, k + 1, j + 74, 2);
        world.setBlock(i + 3, k + 1, j + 75, 2);
        world.setBlock(i + 3, k + 1, j + 76, 2);
        world.setBlock(i + 3, k + 1, j + 77, 2);
        world.setBlock(i + 3, k + 1, j + 78, 2);
        world.setBlock(i + 3, k + 1, j + 79, 2);
        world.setBlock(i + 3, k + 1, j + 80, 2);
        world.setBlock(i + 3, k + 1, j + 81, 2);
        world.setBlock(i + 3, k + 1, j + 82, 2);
        world.setBlock(i + 3, k + 1, j + 83, 2);
        world.setBlock(i + 3, k + 1, j + 84, 2);
        world.setBlock(i + 3, k + 1, j + 85, 2);
        world.setBlock(i + 3, k + 1, j + 86, 2);
        world.setBlock(i + 3, k + 1, j + 87, 2);
        world.setBlock(i + 3, k + 1, j + 88, 2);
        world1.setBlockWithMetadata(i + 3, k + 2, j + 28, 31, 1);
        world1.setBlockWithMetadata(i + 3, k + 2, j + 36, 31, 1);
        world1.setBlockWithMetadata(i + 3, k + 2, j + 37, 31, 1);
        world1.setBlockWithMetadata(i + 3, k + 2, j + 43, 31, 1);
        world1.setBlockWithMetadata(i + 3, k + 2, j + 44, 31, 1);
        world1.setBlockWithMetadata(i + 3, k + 2, j + 45, 31, 1);
        world1.setBlockWithMetadata(i + 3, k + 2, j + 46, 31, 1);
        world1.setBlockWithMetadata(i + 3, k + 2, j + 47, 31, 1);
        world1.setBlockWithMetadata(i + 3, k + 2, j + 48, 31, 1);
        world.setBlock(i + 3, k + 2, j + 59, 37);
        world1.setBlockWithMetadata(i + 3, k + 2, j + 60, 31, 1);
        world1.setBlockWithMetadata(i + 3, k + 2, j + 65, 31, 1);
        world1.setBlockWithMetadata(i + 3, k + 2, j + 66, 31, 1);
        world1.setBlockWithMetadata(i + 3, k + 2, j + 67, 31, 1);
        world.setBlock(i + 3, k + 2, j + 69, 17);
        world1.setBlockWithMetadata(i + 3, k + 2, j + 70, 31, 1);
        world1.setBlockWithMetadata(i + 3, k + 2, j + 71, 31, 1);
        world1.setBlockWithMetadata(i + 3, k + 2, j + 72, 31, 1);
        world1.setBlockWithMetadata(i + 3, k + 2, j + 73, 31, 1);
        world1.setBlockWithMetadata(i + 3, k + 2, j + 75, 31, 1);
        world1.setBlockWithMetadata(i + 3, k + 2, j + 76, 31, 1);
        world1.setBlockWithMetadata(i + 3, k + 2, j + 77, 31, 1);
        world.setBlock(i + 3, k + 2, j + 78, 37);
        world1.setBlockWithMetadata(i + 3, k + 2, j + 79, 31, 1);
        world1.setBlockWithMetadata(i + 3, k + 2, j + 80, 31, 1);
        world1.setBlockWithMetadata(i + 3, k + 2, j + 81, 31, 1);
        world1.setBlockWithMetadata(i + 3, k + 2, j + 82, 31, 1);
        world1.setBlockWithMetadata(i + 3, k + 2, j + 84, 31, 1);
        world1.setBlockWithMetadata(i + 3, k + 2, j + 85, 31, 1);
        world1.setBlockWithMetadata(i + 3, k + 2, j + 86, 31, 1);
        world1.setBlockWithMetadata(i + 3, k + 2, j + 87, 31, 1);
        world1.setBlockWithMetadata(i + 3, k + 2, j + 88, 31, 1);
        world.setBlock(i + 3, k + 3, j + 18, 18);
        world.setBlock(i + 3, k + 3, j + 19, 18);
        world.setBlock(i + 3, k + 3, j + 20, 18);
        world.setBlock(i + 3, k + 3, j + 21, 18);
        world.setBlock(i + 3, k + 3, j + 22, 18);
        world.setBlock(i + 3, k + 3, j + 69, 17);
        world.setBlock(i + 3, k + 4, j + 19, 18);
        world.setBlock(i + 3, k + 4, j + 20, 18);
        world.setBlock(i + 3, k + 4, j + 21, 18);
        world.setBlock(i + 3, k + 4, j + 67, 18);
        world.setBlock(i + 3, k + 4, j + 68, 18);
        world.setBlock(i + 3, k + 4, j + 69, 17);
        world.setBlock(i + 3, k + 4, j + 70, 18);
        world.setBlock(i + 3, k + 4, j + 71, 18);
        world.setBlock(i + 3, k + 5, j + 67, 18);
        world.setBlock(i + 3, k + 5, j + 68, 18);
        world.setBlock(i + 3, k + 5, j + 69, 17);
        world.setBlock(i + 3, k + 5, j + 70, 18);
        world.setBlock(i + 3, k + 5, j + 71, 18);
        world.setBlock(i + 3, k + 6, j + 68, 18);
        world.setBlock(i + 3, k + 6, j + 69, 17);
        world.setBlock(i + 3, k + 6, j + 70, 18);
        world.setBlock(i + 3, k + 7, j + 68, 18);
        world.setBlock(i + 3, k + 7, j + 69, 18);
        world.setBlock(i + 3, k + 7, j + 70, 18);
        world.setBlock(i + 4, k + 0, j + 1, 2);
        world.setBlock(i + 4, k + 0, j + 2, 2);
        world.setBlock(i + 4, k + 0, j + 3, 2);
        world.setBlock(i + 4, k + 0, j + 4, 2);
        world.setBlock(i + 4, k + 0, j + 5, 2);
        world.setBlock(i + 4, k + 0, j + 6, 2);
        world.setBlock(i + 4, k + 0, j + 7, 2);
        world.setBlock(i + 4, k + 0, j + 8, 2);
        world.setBlock(i + 4, k + 0, j + 9, 2);
        world.setBlock(i + 4, k + 0, j + 10, 2);
        world.setBlock(i + 4, k + 0, j + 11, 2);
        world.setBlock(i + 4, k + 0, j + 12, 2);
        world.setBlock(i + 4, k + 0, j + 13, 2);
        world.setBlock(i + 4, k + 0, j + 14, 2);
        world.setBlock(i + 4, k + 0, j + 15, 2);
        world.setBlock(i + 4, k + 0, j + 16, 2);
        world.setBlock(i + 4, k + 0, j + 17, 2);
        world.setBlock(i + 4, k + 0, j + 18, 2);
        world.setBlock(i + 4, k + 0, j + 19, 2);
        world.setBlock(i + 4, k + 0, j + 20, 2);
        world.setBlock(i + 4, k + 0, j + 21, 2);
        world.setBlock(i + 4, k + 0, j + 22, 2);
        world.setBlock(i + 4, k + 0, j + 23, 2);
        world.setBlock(i + 4, k + 0, j + 24, 2);
        world.setBlock(i + 4, k + 0, j + 25, 2);
        world.setBlock(i + 4, k + 0, j + 26, 2);
        world.setBlock(i + 4, k + 0, j + 27, 2);
        world.setBlock(i + 4, k + 0, j + 28, 2);
        world.setBlock(i + 4, k + 0, j + 29, 2);
        world.setBlock(i + 4, k + 0, j + 30, 3);
        world.setBlock(i + 4, k + 0, j + 31, 3);
        world.setBlock(i + 4, k + 0, j + 32, 3);
        world.setBlock(i + 4, k + 0, j + 33, 3);
        world.setBlock(i + 4, k + 0, j + 34, 3);
        world.setBlock(i + 4, k + 0, j + 35, 3);
        world.setBlock(i + 4, k + 0, j + 36, 3);
        world.setBlock(i + 4, k + 0, j + 37, 3);
        world.setBlock(i + 4, k + 0, j + 38, 3);
        world.setBlock(i + 4, k + 0, j + 39, 2);
        world.setBlock(i + 4, k + 0, j + 40, 2);
        world.setBlock(i + 4, k + 0, j + 41, 2);
        world.setBlock(i + 4, k + 0, j + 42, 2);
        world.setBlock(i + 4, k + 0, j + 43, 3);
        world.setBlock(i + 4, k + 0, j + 44, 3);
        world.setBlock(i + 4, k + 0, j + 45, 3);
        world.setBlock(i + 4, k + 0, j + 46, 3);
        world.setBlock(i + 4, k + 0, j + 47, 3);
        world.setBlock(i + 4, k + 0, j + 48, 3);
        world.setBlock(i + 4, k + 0, j + 49, 3);
        world.setBlock(i + 4, k + 0, j + 50, 3);
        world.setBlock(i + 4, k + 0, j + 51, 13);
        world.setBlock(i + 4, k + 0, j + 52, 13);
        world.setBlock(i + 4, k + 0, j + 53, 13);
        world.setBlock(i + 4, k + 0, j + 54, 13);
        world.setBlock(i + 4, k + 0, j + 55, 13);
        world.setBlock(i + 4, k + 0, j + 56, 13);
        world.setBlock(i + 4, k + 0, j + 57, 13);
        world.setBlock(i + 4, k + 0, j + 58, 13);
        world.setBlock(i + 4, k + 0, j + 59, 3);
        world.setBlock(i + 4, k + 0, j + 60, 3);
        world.setBlock(i + 4, k + 0, j + 61, 3);
        world.setBlock(i + 4, k + 0, j + 62, 3);
        world.setBlock(i + 4, k + 0, j + 63, 3);
        world.setBlock(i + 4, k + 0, j + 64, 3);
        world.setBlock(i + 4, k + 0, j + 65, 3);
        world.setBlock(i + 4, k + 0, j + 66, 3);
        world.setBlock(i + 4, k + 0, j + 67, 3);
        world.setBlock(i + 4, k + 0, j + 68, 3);
        world.setBlock(i + 4, k + 0, j + 69, 3);
        world.setBlock(i + 4, k + 0, j + 70, 3);
        world.setBlock(i + 4, k + 0, j + 71, 3);
        world.setBlock(i + 4, k + 0, j + 72, 3);
        world.setBlock(i + 4, k + 0, j + 73, 3);
        world.setBlock(i + 4, k + 0, j + 74, 3);
        world.setBlock(i + 4, k + 0, j + 75, 3);
        world.setBlock(i + 4, k + 0, j + 76, 3);
        world.setBlock(i + 4, k + 0, j + 77, 3);
        world.setBlock(i + 4, k + 0, j + 78, 3);
        world.setBlock(i + 4, k + 0, j + 79, 3);
        world.setBlock(i + 4, k + 0, j + 80, 3);
        world.setBlock(i + 4, k + 0, j + 81, 3);
        world.setBlock(i + 4, k + 0, j + 82, 3);
        world.setBlock(i + 4, k + 0, j + 83, 3);
        world.setBlock(i + 4, k + 0, j + 84, 3);
        world.setBlock(i + 4, k + 0, j + 85, 3);
        world.setBlock(i + 4, k + 0, j + 86, 3);
        world.setBlock(i + 4, k + 0, j + 87, 3);
        world.setBlock(i + 4, k + 0, j + 88, 3);
        world.setBlock(i + 4, k + 0, j + 89, 2);
        world1.setBlockWithMetadata(i + 4, k + 1, j + 7, 31, 1);
        world1.setBlockWithMetadata(i + 4, k + 1, j + 8, 31, 1);
        world.setBlock(i + 4, k + 1, j + 9, 37);
        world1.setBlockWithMetadata(i + 4, k + 1, j + 10, 31, 1);
        world1.setBlockWithMetadata(i + 4, k + 1, j + 11, 31, 1);
        world1.setBlockWithMetadata(i + 4, k + 1, j + 12, 31, 1);
        world1.setBlockWithMetadata(i + 4, k + 1, j + 24, 31, 1);
        world1.setBlockWithMetadata(i + 4, k + 1, j + 25, 31, 1);
        world1.setBlockWithMetadata(i + 4, k + 1, j + 26, 31, 1);
        world1.setBlockWithMetadata(i + 4, k + 1, j + 27, 31, 1);
        world1.setBlockWithMetadata(i + 4, k + 1, j + 28, 31, 1);
        world.setBlock(i + 4, k + 1, j + 30, 2);
        world.setBlock(i + 4, k + 1, j + 31, 2);
        world.setBlock(i + 4, k + 1, j + 32, 2);
        world.setBlock(i + 4, k + 1, j + 33, 2);
        world.setBlock(i + 4, k + 1, j + 34, 2);
        world.setBlock(i + 4, k + 1, j + 35, 2);
        world.setBlock(i + 4, k + 1, j + 36, 2);
        world.setBlock(i + 4, k + 1, j + 37, 2);
        world.setBlock(i + 4, k + 1, j + 38, 2);
        world.setBlock(i + 4, k + 1, j + 43, 2);
        world.setBlock(i + 4, k + 1, j + 44, 2);
        world.setBlock(i + 4, k + 1, j + 45, 2);
        world.setBlock(i + 4, k + 1, j + 46, 2);
        world.setBlock(i + 4, k + 1, j + 47, 2);
        world.setBlock(i + 4, k + 1, j + 48, 2);
        world.setBlock(i + 4, k + 1, j + 49, 2);
        world.setBlock(i + 4, k + 1, j + 50, 2);
        world.setBlock(i + 4, k + 1, j + 51, 13);
        world.setBlock(i + 4, k + 1, j + 52, 13);
        world.setBlock(i + 4, k + 1, j + 53, 13);
        world.setBlock(i + 4, k + 1, j + 54, 13);
        world.setBlock(i + 4, k + 1, j + 55, 13);
        world.setBlock(i + 4, k + 1, j + 56, 13);
        world.setBlock(i + 4, k + 1, j + 57, 13);
        world.setBlock(i + 4, k + 1, j + 58, 13);
        world.setBlock(i + 4, k + 1, j + 59, 2);
        world.setBlock(i + 4, k + 1, j + 60, 2);
        world.setBlock(i + 4, k + 1, j + 61, 2);
        world.setBlock(i + 4, k + 1, j + 62, 2);
        world.setBlock(i + 4, k + 1, j + 63, 2);
        world.setBlock(i + 4, k + 1, j + 64, 2);
        world.setBlock(i + 4, k + 1, j + 65, 2);
        world.setBlock(i + 4, k + 1, j + 66, 2);
        world.setBlock(i + 4, k + 1, j + 67, 2);
        world.setBlock(i + 4, k + 1, j + 68, 2);
        world.setBlock(i + 4, k + 1, j + 69, 2);
        world.setBlock(i + 4, k + 1, j + 70, 2);
        world.setBlock(i + 4, k + 1, j + 71, 2);
        world.setBlock(i + 4, k + 1, j + 72, 2);
        world.setBlock(i + 4, k + 1, j + 73, 2);
        world.setBlock(i + 4, k + 1, j + 74, 2);
        world.setBlock(i + 4, k + 1, j + 75, 2);
        world.setBlock(i + 4, k + 1, j + 76, 2);
        world.setBlock(i + 4, k + 1, j + 77, 2);
        world.setBlock(i + 4, k + 1, j + 78, 2);
        world.setBlock(i + 4, k + 1, j + 79, 3);
        world.setBlock(i + 4, k + 1, j + 80, 3);
        world.setBlock(i + 4, k + 1, j + 81, 3);
        world.setBlock(i + 4, k + 1, j + 82, 2);
        world.setBlock(i + 4, k + 1, j + 83, 2);
        world.setBlock(i + 4, k + 1, j + 84, 2);
        world.setBlock(i + 4, k + 1, j + 85, 2);
        world.setBlock(i + 4, k + 1, j + 86, 2);
        world.setBlock(i + 4, k + 1, j + 87, 2);
        world.setBlock(i + 4, k + 1, j + 88, 2);
        world1.setBlockWithMetadata(i + 4, k + 2, j + 37, 31, 1);
        world1.setBlockWithMetadata(i + 4, k + 2, j + 43, 31, 1);
        world.setBlock(i + 4, k + 2, j + 44, 38);
        world1.setBlockWithMetadata(i + 4, k + 2, j + 45, 31, 1);
        world1.setBlockWithMetadata(i + 4, k + 2, j + 46, 31, 1);
        world1.setBlockWithMetadata(i + 4, k + 2, j + 47, 31, 1);
        world1.setBlockWithMetadata(i + 4, k + 2, j + 48, 31, 1);
        world1.setBlockWithMetadata(i + 4, k + 2, j + 49, 31, 1);
        world1.setBlockWithMetadata(i + 4, k + 2, j + 50, 31, 1);
        world1.setBlockWithMetadata(i + 4, k + 2, j + 61, 31, 1);
        world1.setBlockWithMetadata(i + 4, k + 2, j + 63, 31, 1);
        world1.setBlockWithMetadata(i + 4, k + 2, j + 64, 31, 1);
        world1.setBlockWithMetadata(i + 4, k + 2, j + 65, 31, 1);
        world.setBlock(i + 4, k + 2, j + 66, 38);
        world1.setBlockWithMetadata(i + 4, k + 2, j + 67, 31, 1);
        world1.setBlockWithMetadata(i + 4, k + 2, j + 68, 31, 1);
        world1.setBlockWithMetadata(i + 4, k + 2, j + 69, 31, 1);
        world1.setBlockWithMetadata(i + 4, k + 2, j + 71, 31, 1);
        world1.setBlockWithMetadata(i + 4, k + 2, j + 72, 31, 1);
        world1.setBlockWithMetadata(i + 4, k + 2, j + 73, 31, 1);
        world.setBlock(i + 4, k + 2, j + 75, 38);
        world1.setBlockWithMetadata(i + 4, k + 2, j + 77, 31, 1);
        world.setBlock(i + 4, k + 2, j + 79, 4);
        world.setBlock(i + 4, k + 2, j + 80, 4);
        world.setBlock(i + 4, k + 2, j + 81, 4);
        world1.setBlockWithMetadata(i + 4, k + 2, j + 83, 31, 1);
        world1.setBlockWithMetadata(i + 4, k + 2, j + 85, 31, 1);
        world.setBlock(i + 4, k + 2, j + 86, 38);
        world1.setBlockWithMetadata(i + 4, k + 2, j + 87, 31, 1);
        world.setBlock(i + 4, k + 3, j + 18, 18);
        world.setBlock(i + 4, k + 3, j + 19, 18);
        world.setBlock(i + 4, k + 3, j + 20, 18);
        world.setBlock(i + 4, k + 3, j + 21, 18);
        world.setBlock(i + 4, k + 3, j + 22, 18);
        world.setBlock(i + 4, k + 3, j + 79, 4);
        world.setBlock(i + 4, k + 3, j + 81, 4);
        world.setBlock(i + 4, k + 4, j + 18, 18);
        world.setBlock(i + 4, k + 4, j + 19, 18);
        world.setBlock(i + 4, k + 4, j + 20, 18);
        world.setBlock(i + 4, k + 4, j + 21, 18);
        world.setBlock(i + 4, k + 4, j + 22, 18);
        world.setBlock(i + 4, k + 4, j + 67, 18);
        world.setBlock(i + 4, k + 4, j + 68, 18);
        world.setBlock(i + 4, k + 4, j + 69, 18);
        world.setBlock(i + 4, k + 4, j + 70, 18);
        world.setBlock(i + 4, k + 4, j + 71, 18);
        world.setBlock(i + 4, k + 4, j + 79, 67);
        world.setBlock(i + 4, k + 4, j + 81, 67);
        world.setBlock(i + 4, k + 5, j + 19, 18);
        world.setBlock(i + 4, k + 5, j + 20, 18);
        world.setBlock(i + 4, k + 5, j + 67, 18);
        world.setBlock(i + 4, k + 5, j + 68, 18);
        world.setBlock(i + 4, k + 5, j + 69, 18);
        world.setBlock(i + 4, k + 5, j + 70, 18);
        world.setBlock(i + 4, k + 5, j + 71, 18);
        world.setBlock(i + 4, k + 6, j + 20, 18);
        world.setBlock(i + 4, k + 6, j + 69, 18);
        world.setBlock(i + 4, k + 6, j + 70, 18);
        world.setBlock(i + 4, k + 7, j + 69, 18);
        world.setBlock(i + 4, k + 13, j + 79, 4);
        world.setBlock(i + 4, k + 13, j + 80, 4);
        world.setBlock(i + 4, k + 13, j + 81, 4);
        world.setBlock(i + 4, k + 14, j + 79, 4);
        world.setBlock(i + 4, k + 14, j + 80, 4);
        world.setBlock(i + 4, k + 14, j + 81, 4);
        world.setBlock(i + 4, k + 15, j + 79, 67);
        world.setBlock(i + 4, k + 15, j + 81, 67);
        world.setBlock(i + 5, k + 0, j + 1, 2);
        world.setBlock(i + 5, k + 0, j + 2, 2);
        world.setBlock(i + 5, k + 0, j + 3, 2);
        world.setBlock(i + 5, k + 0, j + 4, 2);
        world.setBlock(i + 5, k + 0, j + 5, 2);
        world.setBlock(i + 5, k + 0, j + 6, 2);
        world.setBlock(i + 5, k + 0, j + 7, 2);
        world.setBlock(i + 5, k + 0, j + 8, 2);
        world.setBlock(i + 5, k + 0, j + 9, 2);
        world.setBlock(i + 5, k + 0, j + 10, 2);
        world.setBlock(i + 5, k + 0, j + 11, 2);
        world.setBlock(i + 5, k + 0, j + 12, 2);
        world.setBlock(i + 5, k + 0, j + 13, 2);
        world.setBlock(i + 5, k + 0, j + 14, 2);
        world.setBlock(i + 5, k + 0, j + 15, 3);
        world.setBlock(i + 5, k + 0, j + 16, 3);
        world.setBlock(i + 5, k + 0, j + 17, 2);
        world.setBlock(i + 5, k + 0, j + 18, 2);
        world.setBlock(i + 5, k + 0, j + 19, 2);
        world.setBlock(i + 5, k + 0, j + 20, 3);
        world.setBlock(i + 5, k + 0, j + 21, 2);
        world.setBlock(i + 5, k + 0, j + 22, 2);
        world.setBlock(i + 5, k + 0, j + 23, 2);
        world.setBlock(i + 5, k + 0, j + 24, 2);
        world.setBlock(i + 5, k + 0, j + 25, 2);
        world.setBlock(i + 5, k + 0, j + 26, 2);
        world.setBlock(i + 5, k + 0, j + 27, 2);
        world.setBlock(i + 5, k + 0, j + 28, 2);
        world.setBlock(i + 5, k + 0, j + 29, 3);
        world.setBlock(i + 5, k + 0, j + 30, 3);
        world.setBlock(i + 5, k + 0, j + 31, 3);
        world.setBlock(i + 5, k + 0, j + 32, 3);
        world.setBlock(i + 5, k + 0, j + 33, 3);
        world.setBlock(i + 5, k + 0, j + 34, 3);
        world.setBlock(i + 5, k + 0, j + 35, 3);
        world.setBlock(i + 5, k + 0, j + 36, 3);
        world.setBlock(i + 5, k + 0, j + 37, 3);
        world.setBlock(i + 5, k + 0, j + 38, 3);
        world.setBlock(i + 5, k + 0, j + 39, 3);
        world.setBlock(i + 5, k + 0, j + 40, 2);
        world.setBlock(i + 5, k + 0, j + 41, 2);
        world.setBlock(i + 5, k + 0, j + 42, 2);
        world.setBlock(i + 5, k + 0, j + 43, 3);
        world.setBlock(i + 5, k + 0, j + 44, 3);
        world.setBlock(i + 5, k + 0, j + 45, 3);
        world.setBlock(i + 5, k + 0, j + 46, 3);
        world.setBlock(i + 5, k + 0, j + 47, 3);
        world.setBlock(i + 5, k + 0, j + 48, 3);
        world.setBlock(i + 5, k + 0, j + 49, 3);
        world.setBlock(i + 5, k + 0, j + 50, 3);
        world.setBlock(i + 5, k + 0, j + 51, 13);
        world.setBlock(i + 5, k + 0, j + 52, 13);
        world.setBlock(i + 5, k + 0, j + 53, 13);
        world.setBlock(i + 5, k + 0, j + 54, 13);
        world.setBlock(i + 5, k + 0, j + 55, 13);
        world.setBlock(i + 5, k + 0, j + 56, 13);
        world.setBlock(i + 5, k + 0, j + 57, 13);
        world.setBlock(i + 5, k + 0, j + 58, 13);
        world.setBlock(i + 5, k + 0, j + 59, 3);
        world.setBlock(i + 5, k + 0, j + 60, 3);
        world.setBlock(i + 5, k + 0, j + 61, 3);
        world.setBlock(i + 5, k + 0, j + 62, 3);
        world.setBlock(i + 5, k + 0, j + 63, 3);
        world.setBlock(i + 5, k + 0, j + 64, 3);
        world.setBlock(i + 5, k + 0, j + 65, 3);
        world.setBlock(i + 5, k + 0, j + 66, 3);
        world.setBlock(i + 5, k + 0, j + 67, 3);
        world.setBlock(i + 5, k + 0, j + 68, 3);
        world.setBlock(i + 5, k + 0, j + 69, 3);
        world.setBlock(i + 5, k + 0, j + 70, 3);
        world.setBlock(i + 5, k + 0, j + 71, 3);
        world.setBlock(i + 5, k + 0, j + 72, 3);
        world.setBlock(i + 5, k + 0, j + 73, 3);
        world.setBlock(i + 5, k + 0, j + 74, 3);
        world.setBlock(i + 5, k + 0, j + 75, 3);
        world.setBlock(i + 5, k + 0, j + 76, 3);
        world.setBlock(i + 5, k + 0, j + 77, 3);
        world.setBlock(i + 5, k + 0, j + 78, 3);
        world.setBlock(i + 5, k + 0, j + 79, 3);
        world.setBlock(i + 5, k + 0, j + 80, 3);
        world.setBlock(i + 5, k + 0, j + 81, 3);
        world.setBlock(i + 5, k + 0, j + 82, 3);
        world.setBlock(i + 5, k + 0, j + 83, 3);
        world.setBlock(i + 5, k + 0, j + 84, 3);
        world.setBlock(i + 5, k + 0, j + 85, 3);
        world.setBlock(i + 5, k + 0, j + 86, 3);
        world.setBlock(i + 5, k + 0, j + 87, 3);
        world.setBlock(i + 5, k + 0, j + 88, 3);
        world.setBlock(i + 5, k + 0, j + 89, 2);
        world.setBlock(i + 5, k + 1, j + 8, 38);
        world1.setBlockWithMetadata(i + 5, k + 1, j + 9, 31, 1);
        world1.setBlockWithMetadata(i + 5, k + 1, j + 10, 31, 1);
        world1.setBlockWithMetadata(i + 5, k + 1, j + 11, 31, 1);
        world1.setBlockWithMetadata(i + 5, k + 1, j + 12, 31, 1);
        world.setBlock(i + 5, k + 1, j + 15, 2);
        world.setBlock(i + 5, k + 1, j + 16, 2);
        world.setBlock(i + 5, k + 1, j + 20, 17);
        world1.setBlockWithMetadata(i + 5, k + 1, j + 24, 31, 1);
        world1.setBlockWithMetadata(i + 5, k + 1, j + 25, 31, 1);
        world1.setBlockWithMetadata(i + 5, k + 1, j + 26, 31, 1);
        world.setBlock(i + 5, k + 1, j + 29, 2);
        world.setBlock(i + 5, k + 1, j + 30, 2);
        world.setBlock(i + 5, k + 1, j + 31, 2);
        world.setBlock(i + 5, k + 1, j + 32, 2);
        world.setBlock(i + 5, k + 1, j + 33, 2);
        world.setBlock(i + 5, k + 1, j + 34, 2);
        world.setBlock(i + 5, k + 1, j + 35, 2);
        world.setBlock(i + 5, k + 1, j + 36, 2);
        world.setBlock(i + 5, k + 1, j + 37, 2);
        world.setBlock(i + 5, k + 1, j + 38, 2);
        world.setBlock(i + 5, k + 1, j + 39, 2);
        world.setBlock(i + 5, k + 1, j + 43, 2);
        world.setBlock(i + 5, k + 1, j + 44, 2);
        world.setBlock(i + 5, k + 1, j + 45, 2);
        world.setBlock(i + 5, k + 1, j + 46, 2);
        world.setBlock(i + 5, k + 1, j + 47, 2);
        world.setBlock(i + 5, k + 1, j + 48, 2);
        world.setBlock(i + 5, k + 1, j + 49, 2);
        world.setBlock(i + 5, k + 1, j + 50, 2);
        world.setBlock(i + 5, k + 1, j + 51, 13);
        world.setBlock(i + 5, k + 1, j + 52, 13);
        world.setBlock(i + 5, k + 1, j + 53, 13);
        world.setBlock(i + 5, k + 1, j + 54, 13);
        world.setBlock(i + 5, k + 1, j + 55, 13);
        world.setBlock(i + 5, k + 1, j + 56, 13);
        world.setBlock(i + 5, k + 1, j + 57, 13);
        world.setBlock(i + 5, k + 1, j + 58, 13);
        world.setBlock(i + 5, k + 1, j + 59, 2);
        world.setBlock(i + 5, k + 1, j + 60, 2);
        world.setBlock(i + 5, k + 1, j + 61, 2);
        world.setBlock(i + 5, k + 1, j + 62, 2);
        world.setBlock(i + 5, k + 1, j + 63, 2);
        world.setBlock(i + 5, k + 1, j + 64, 2);
        world.setBlock(i + 5, k + 1, j + 65, 2);
        world.setBlock(i + 5, k + 1, j + 66, 2);
        world.setBlock(i + 5, k + 1, j + 67, 2);
        world.setBlock(i + 5, k + 1, j + 68, 2);
        world.setBlock(i + 5, k + 1, j + 69, 2);
        world.setBlock(i + 5, k + 1, j + 70, 2);
        world.setBlock(i + 5, k + 1, j + 71, 2);
        world.setBlock(i + 5, k + 1, j + 72, 2);
        world.setBlock(i + 5, k + 1, j + 73, 2);
        world.setBlock(i + 5, k + 1, j + 74, 2);
        world.setBlock(i + 5, k + 1, j + 75, 2);
        world.setBlock(i + 5, k + 1, j + 76, 2);
        world.setBlock(i + 5, k + 1, j + 77, 2);
        world.setBlock(i + 5, k + 1, j + 78, 3);
        world.setBlock(i + 5, k + 1, j + 79, 3);
        world.setBlock(i + 5, k + 1, j + 80, 3);
        world.setBlock(i + 5, k + 1, j + 81, 3);
        world.setBlock(i + 5, k + 1, j + 82, 3);
        world.setBlock(i + 5, k + 1, j + 83, 2);
        world.setBlock(i + 5, k + 1, j + 84, 2);
        world.setBlock(i + 5, k + 1, j + 85, 2);
        world.setBlock(i + 5, k + 1, j + 86, 2);
        world.setBlock(i + 5, k + 1, j + 87, 2);
        world.setBlock(i + 5, k + 1, j + 88, 2);
        world.setBlock(i + 5, k + 2, j + 20, 17);
        world1.setBlockWithMetadata(i + 5, k + 2, j + 35, 31, 1);
        world1.setBlockWithMetadata(i + 5, k + 2, j + 36, 31, 1);
        world1.setBlockWithMetadata(i + 5, k + 2, j + 37, 31, 1);
        world1.setBlockWithMetadata(i + 5, k + 2, j + 38, 31, 1);
        world1.setBlockWithMetadata(i + 5, k + 2, j + 39, 31, 1);
        world1.setBlockWithMetadata(i + 5, k + 2, j + 43, 31, 1);
        world1.setBlockWithMetadata(i + 5, k + 2, j + 44, 31, 1);
        world.setBlock(i + 5, k + 2, j + 45, 38);
        world1.setBlockWithMetadata(i + 5, k + 2, j + 49, 31, 1);
        world1.setBlockWithMetadata(i + 5, k + 2, j + 65, 31, 1);
        world1.setBlockWithMetadata(i + 5, k + 2, j + 66, 31, 1);
        world1.setBlockWithMetadata(i + 5, k + 2, j + 67, 31, 1);
        world1.setBlockWithMetadata(i + 5, k + 2, j + 68, 31, 1);
        world1.setBlockWithMetadata(i + 5, k + 2, j + 69, 31, 1);
        world1.setBlockWithMetadata(i + 5, k + 2, j + 70, 31, 1);
        world1.setBlockWithMetadata(i + 5, k + 2, j + 71, 31, 1);
        world1.setBlockWithMetadata(i + 5, k + 2, j + 72, 31, 1);
        world1.setBlockWithMetadata(i + 5, k + 2, j + 73, 31, 1);
        world.setBlock(i + 5, k + 2, j + 78, 4);
        world.setBlock(i + 5, k + 2, j + 79, 4);
        world.setBlock(i + 5, k + 2, j + 80, 4);
        world.setBlock(i + 5, k + 2, j + 81, 4);
        world.setBlock(i + 5, k + 2, j + 82, 4);
        world1.setBlockWithMetadata(i + 5, k + 2, j + 84, 31, 1);
        world1.setBlockWithMetadata(i + 5, k + 2, j + 85, 31, 1);
        world1.setBlockWithMetadata(i + 5, k + 2, j + 86, 31, 1);
        world1.setBlockWithMetadata(i + 5, k + 2, j + 87, 31, 1);
        world1.setBlockWithMetadata(i + 5, k + 2, j + 88, 31, 1);
        world.setBlock(i + 5, k + 3, j + 18, 18);
        world.setBlock(i + 5, k + 3, j + 19, 18);
        world.setBlock(i + 5, k + 3, j + 20, 17);
        world.setBlock(i + 5, k + 3, j + 21, 18);
        world.setBlock(i + 5, k + 3, j + 22, 18);
        world1.setBlockWithMetadata(i + 5, k + 3, j + 78, 67, 2);
        world.setBlock(i + 5, k + 3, j + 79, 4);
        world.setBlock(i + 5, k + 3, j + 80, 1);
        world.setBlock(i + 5, k + 3, j + 81, 4);
        world1.setBlockWithMetadata(i + 5, k + 3, j + 82, 67, 3);
        world.setBlock(i + 5, k + 4, j + 2, 18);
        world.setBlock(i + 5, k + 4, j + 3, 18);
        world.setBlock(i + 5, k + 4, j + 4, 18);
        world.setBlock(i + 5, k + 4, j + 5, 18);
        world.setBlock(i + 5, k + 4, j + 6, 18);
        world.setBlock(i + 5, k + 4, j + 18, 18);
        world.setBlock(i + 5, k + 4, j + 19, 18);
        world.setBlock(i + 5, k + 4, j + 20, 17);
        world.setBlock(i + 5, k + 4, j + 21, 18);
        world.setBlock(i + 5, k + 4, j + 22, 18);
        world.setBlock(i + 5, k + 4, j + 67, 18);
        world.setBlock(i + 5, k + 4, j + 68, 18);
        world.setBlock(i + 5, k + 4, j + 69, 18);
        world.setBlock(i + 5, k + 4, j + 70, 18);
        world.setBlock(i + 5, k + 4, j + 79, 4);
        world.setBlock(i + 5, k + 4, j + 80, 1);
        world.setBlock(i + 5, k + 4, j + 81, 4);
        world.setBlock(i + 5, k + 5, j + 3, 18);
        world.setBlock(i + 5, k + 5, j + 4, 18);
        world.setBlock(i + 5, k + 5, j + 5, 18);
        world.setBlock(i + 5, k + 5, j + 6, 18);
        world.setBlock(i + 5, k + 5, j + 19, 18);
        world.setBlock(i + 5, k + 5, j + 20, 17);
        world.setBlock(i + 5, k + 5, j + 21, 18);
        world.setBlock(i + 5, k + 5, j + 68, 18);
        world.setBlock(i + 5, k + 5, j + 69, 18);
        world.setBlock(i + 5, k + 5, j + 70, 18);
        world.setBlock(i + 5, k + 5, j + 71, 18);
        world.setBlock(i + 5, k + 5, j + 79, 4);
        world.setBlock(i + 5, k + 5, j + 80, 1);
        world.setBlock(i + 5, k + 5, j + 81, 4);
        world.setBlock(i + 5, k + 6, j + 19, 18);
        world.setBlock(i + 5, k + 6, j + 20, 18);
        world.setBlock(i + 5, k + 6, j + 21, 18);
        world.setBlock(i + 5, k + 6, j + 79, 4);
        world.setBlock(i + 5, k + 6, j + 80, 1);
        world.setBlock(i + 5, k + 6, j + 81, 4);
        world.setBlock(i + 5, k + 7, j + 79, 4);
        world.setBlock(i + 5, k + 7, j + 80, 1);
        world.setBlock(i + 5, k + 7, j + 81, 4);
        world.setBlock(i + 5, k + 8, j + 79, 4);
        world.setBlock(i + 5, k + 8, j + 80, 1);
        world.setBlock(i + 5, k + 8, j + 81, 4);
        world.setBlock(i + 5, k + 9, j + 79, 4);
        world.setBlock(i + 5, k + 9, j + 80, 1);
        world.setBlock(i + 5, k + 9, j + 81, 4);
        world.setBlock(i + 5, k + 10, j + 79, 4);
        world.setBlock(i + 5, k + 10, j + 80, 1);
        world.setBlock(i + 5, k + 10, j + 81, 4);
        world.setBlock(i + 5, k + 11, j + 79, 4);
        world.setBlock(i + 5, k + 11, j + 80, 1);
        world.setBlock(i + 5, k + 11, j + 81, 4);
        world.setBlock(i + 5, k + 12, j + 79, 4);
        world.setBlock(i + 5, k + 12, j + 80, 1);
        world.setBlock(i + 5, k + 12, j + 81, 4);
        world.setBlock(i + 5, k + 13, j + 78, 4);
        world.setBlock(i + 5, k + 13, j + 79, 4);
        world.setBlock(i + 5, k + 13, j + 80, 1);
        world.setBlock(i + 5, k + 13, j + 81, 4);
        world.setBlock(i + 5, k + 13, j + 82, 4);
        world.setBlock(i + 5, k + 14, j + 78, 4);
        world.setBlock(i + 5, k + 14, j + 82, 4);
        world.setBlock(i + 6, k + 0, j + 1, 2);
        world.setBlock(i + 6, k + 0, j + 2, 2);
        world.setBlock(i + 6, k + 0, j + 3, 2);
        world.setBlock(i + 6, k + 0, j + 4, 2);
        world.setBlock(i + 6, k + 0, j + 5, 2);
        world.setBlock(i + 6, k + 0, j + 6, 2);
        world.setBlock(i + 6, k + 0, j + 7, 2);
        world.setBlock(i + 6, k + 0, j + 8, 2);
        world.setBlock(i + 6, k + 0, j + 9, 2);
        world.setBlock(i + 6, k + 0, j + 10, 2);
        world.setBlock(i + 6, k + 0, j + 11, 2);
        world.setBlock(i + 6, k + 0, j + 12, 2);
        world.setBlock(i + 6, k + 0, j + 13, 2);
        world.setBlock(i + 6, k + 0, j + 14, 3);
        world.setBlock(i + 6, k + 0, j + 15, 3);
        world.setBlock(i + 6, k + 0, j + 16, 3);
        world.setBlock(i + 6, k + 0, j + 17, 2);
        world.setBlock(i + 6, k + 0, j + 18, 2);
        world.setBlock(i + 6, k + 0, j + 19, 2);
        world.setBlock(i + 6, k + 0, j + 20, 2);
        world.setBlock(i + 6, k + 0, j + 21, 2);
        world.setBlock(i + 6, k + 0, j + 22, 2);
        world.setBlock(i + 6, k + 0, j + 23, 2);
        world.setBlock(i + 6, k + 0, j + 24, 2);
        world.setBlock(i + 6, k + 0, j + 25, 2);
        world.setBlock(i + 6, k + 0, j + 26, 2);
        world.setBlock(i + 6, k + 0, j + 27, 2);
        world.setBlock(i + 6, k + 0, j + 28, 3);
        world.setBlock(i + 6, k + 0, j + 29, 3);
        world.setBlock(i + 6, k + 0, j + 30, 3);
        world.setBlock(i + 6, k + 0, j + 31, 3);
        world.setBlock(i + 6, k + 0, j + 32, 3);
        world.setBlock(i + 6, k + 0, j + 33, 3);
        world.setBlock(i + 6, k + 0, j + 34, 3);
        world.setBlock(i + 6, k + 0, j + 35, 3);
        world.setBlock(i + 6, k + 0, j + 36, 3);
        world.setBlock(i + 6, k + 0, j + 37, 3);
        world.setBlock(i + 6, k + 0, j + 38, 3);
        world.setBlock(i + 6, k + 0, j + 39, 3);
        world.setBlock(i + 6, k + 0, j + 40, 3);
        world.setBlock(i + 6, k + 0, j + 41, 3);
        world.setBlock(i + 6, k + 0, j + 42, 3);
        world.setBlock(i + 6, k + 0, j + 43, 3);
        world.setBlock(i + 6, k + 0, j + 44, 3);
        world.setBlock(i + 6, k + 0, j + 45, 3);
        world.setBlock(i + 6, k + 0, j + 46, 3);
        world.setBlock(i + 6, k + 0, j + 47, 3);
        world.setBlock(i + 6, k + 0, j + 48, 3);
        world.setBlock(i + 6, k + 0, j + 49, 3);
        world.setBlock(i + 6, k + 0, j + 50, 3);
        world.setBlock(i + 6, k + 0, j + 51, 3);
        world.setBlock(i + 6, k + 0, j + 52, 13);
        world.setBlock(i + 6, k + 0, j + 53, 13);
        world.setBlock(i + 6, k + 0, j + 54, 13);
        world.setBlock(i + 6, k + 0, j + 55, 13);
        world.setBlock(i + 6, k + 0, j + 56, 13);
        world.setBlock(i + 6, k + 0, j + 57, 13);
        world.setBlock(i + 6, k + 0, j + 58, 3);
        world.setBlock(i + 6, k + 0, j + 59, 3);
        world.setBlock(i + 6, k + 0, j + 60, 3);
        world.setBlock(i + 6, k + 0, j + 61, 3);
        world.setBlock(i + 6, k + 0, j + 62, 3);
        world.setBlock(i + 6, k + 0, j + 63, 3);
        world.setBlock(i + 6, k + 0, j + 64, 3);
        world.setBlock(i + 6, k + 0, j + 65, 3);
        world.setBlock(i + 6, k + 0, j + 66, 3);
        world.setBlock(i + 6, k + 0, j + 67, 3);
        world.setBlock(i + 6, k + 0, j + 68, 3);
        world.setBlock(i + 6, k + 0, j + 69, 3);
        world.setBlock(i + 6, k + 0, j + 70, 3);
        world.setBlock(i + 6, k + 0, j + 71, 3);
        world.setBlock(i + 6, k + 0, j + 72, 3);
        world.setBlock(i + 6, k + 0, j + 73, 3);
        world.setBlock(i + 6, k + 0, j + 74, 3);
        world.setBlock(i + 6, k + 0, j + 75, 3);
        world.setBlock(i + 6, k + 0, j + 76, 3);
        world.setBlock(i + 6, k + 0, j + 77, 3);
        world.setBlock(i + 6, k + 0, j + 78, 3);
        world.setBlock(i + 6, k + 0, j + 79, 3);
        world.setBlock(i + 6, k + 0, j + 80, 3);
        world.setBlock(i + 6, k + 0, j + 81, 3);
        world.setBlock(i + 6, k + 0, j + 82, 3);
        world.setBlock(i + 6, k + 0, j + 83, 3);
        world.setBlock(i + 6, k + 0, j + 84, 3);
        world.setBlock(i + 6, k + 0, j + 85, 3);
        world.setBlock(i + 6, k + 0, j + 86, 3);
        world.setBlock(i + 6, k + 0, j + 87, 3);
        world.setBlock(i + 6, k + 0, j + 88, 2);
        world.setBlock(i + 6, k + 0, j + 89, 2);
        world.setBlock(i + 6, k + 0, j + 90, 2);
        world1.setBlockWithMetadata(i + 6, k + 1, j + 8, 31, 1);
        world1.setBlockWithMetadata(i + 6, k + 1, j + 9, 31, 1);
        world.setBlock(i + 6, k + 1, j + 10, 37);
        world1.setBlockWithMetadata(i + 6, k + 1, j + 11, 31, 1);
        world1.setBlockWithMetadata(i + 6, k + 1, j + 12, 31, 1);
        world1.setBlockWithMetadata(i + 6, k + 1, j + 13, 31, 1);
        world.setBlock(i + 6, k + 1, j + 14, 2);
        world.setBlock(i + 6, k + 1, j + 15, 2);
        world.setBlock(i + 6, k + 1, j + 16, 2);
        world1.setBlockWithMetadata(i + 6, k + 1, j + 18, 31, 1);
        world.setBlock(i + 6, k + 1, j + 21, 37);
        world1.setBlockWithMetadata(i + 6, k + 1, j + 24, 31, 1);
        world.setBlock(i + 6, k + 1, j + 26, 38);
        world1.setBlockWithMetadata(i + 6, k + 1, j + 27, 31, 1);
        world.setBlock(i + 6, k + 1, j + 28, 2);
        world.setBlock(i + 6, k + 1, j + 29, 2);
        world.setBlock(i + 6, k + 1, j + 30, 2);
        world.setBlock(i + 6, k + 1, j + 31, 2);
        world.setBlock(i + 6, k + 1, j + 32, 2);
        world.setBlock(i + 6, k + 1, j + 33, 2);
        world.setBlock(i + 6, k + 1, j + 34, 2);
        world.setBlock(i + 6, k + 1, j + 35, 2);
        world.setBlock(i + 6, k + 1, j + 36, 2);
        world.setBlock(i + 6, k + 1, j + 37, 2);
        world.setBlock(i + 6, k + 1, j + 38, 2);
        world.setBlock(i + 6, k + 1, j + 39, 2);
        world.setBlock(i + 6, k + 1, j + 40, 2);
        world.setBlock(i + 6, k + 1, j + 41, 2);
        world.setBlock(i + 6, k + 1, j + 42, 2);
        world.setBlock(i + 6, k + 1, j + 43, 2);
        world.setBlock(i + 6, k + 1, j + 44, 2);
        world.setBlock(i + 6, k + 1, j + 45, 2);
        world.setBlock(i + 6, k + 1, j + 46, 2);
        world.setBlock(i + 6, k + 1, j + 47, 2);
        world.setBlock(i + 6, k + 1, j + 48, 2);
        world.setBlock(i + 6, k + 1, j + 49, 2);
        world.setBlock(i + 6, k + 1, j + 50, 2);
        world.setBlock(i + 6, k + 1, j + 51, 2);
        world.setBlock(i + 6, k + 1, j + 52, 13);
        world.setBlock(i + 6, k + 1, j + 53, 13);
        world.setBlock(i + 6, k + 1, j + 54, 13);
        world.setBlock(i + 6, k + 1, j + 55, 13);
        world.setBlock(i + 6, k + 1, j + 56, 13);
        world.setBlock(i + 6, k + 1, j + 57, 13);
        world.setBlock(i + 6, k + 1, j + 58, 2);
        world.setBlock(i + 6, k + 1, j + 59, 2);
        world.setBlock(i + 6, k + 1, j + 60, 2);
        world.setBlock(i + 6, k + 1, j + 61, 2);
        world.setBlock(i + 6, k + 1, j + 62, 2);
        world.setBlock(i + 6, k + 1, j + 63, 2);
        world.setBlock(i + 6, k + 1, j + 64, 2);
        world.setBlock(i + 6, k + 1, j + 65, 2);
        world.setBlock(i + 6, k + 1, j + 66, 2);
        world.setBlock(i + 6, k + 1, j + 67, 2);
        world.setBlock(i + 6, k + 1, j + 68, 2);
        world.setBlock(i + 6, k + 1, j + 69, 2);
        world.setBlock(i + 6, k + 1, j + 70, 2);
        world.setBlock(i + 6, k + 1, j + 71, 2);
        world.setBlock(i + 6, k + 1, j + 72, 2);
        world.setBlock(i + 6, k + 1, j + 73, 2);
        world.setBlock(i + 6, k + 1, j + 74, 2);
        world.setBlock(i + 6, k + 1, j + 75, 2);
        world.setBlock(i + 6, k + 1, j + 76, 2);
        world.setBlock(i + 6, k + 1, j + 77, 3);
        world.setBlock(i + 6, k + 1, j + 78, 3);
        world.setBlock(i + 6, k + 1, j + 79, 3);
        world.setBlock(i + 6, k + 1, j + 80, 3);
        world.setBlock(i + 6, k + 1, j + 81, 3);
        world.setBlock(i + 6, k + 1, j + 82, 3);
        world.setBlock(i + 6, k + 1, j + 83, 3);
        world.setBlock(i + 6, k + 1, j + 84, 2);
        world.setBlock(i + 6, k + 1, j + 85, 2);
        world.setBlock(i + 6, k + 1, j + 86, 2);
        world.setBlock(i + 6, k + 1, j + 87, 2);
        world1.setBlockWithMetadata(i + 6, k + 2, j + 31, 31, 1);
        world1.setBlockWithMetadata(i + 6, k + 2, j + 36, 31, 1);
        world1.setBlockWithMetadata(i + 6, k + 2, j + 37, 31, 1);
        world1.setBlockWithMetadata(i + 6, k + 2, j + 38, 31, 1);
        world.setBlock(i + 6, k + 2, j + 51, 85);
        world.setBlock(i + 6, k + 2, j + 58, 85);
        world1.setBlockWithMetadata(i + 6, k + 2, j + 68, 31, 1);
        world1.setBlockWithMetadata(i + 6, k + 2, j + 72, 31, 1);
        world1.setBlockWithMetadata(i + 6, k + 2, j + 73, 31, 1);
        world1.setBlockWithMetadata(i + 6, k + 2, j + 74, 31, 1);
        world.setBlock(i + 6, k + 2, j + 77, 4);
        world.setBlock(i + 6, k + 2, j + 78, 4);
        world.setBlock(i + 6, k + 2, j + 79, 4);
        world.setBlock(i + 6, k + 2, j + 80, 4);
        world.setBlock(i + 6, k + 2, j + 81, 4);
        world.setBlock(i + 6, k + 2, j + 82, 4);
        world.setBlock(i + 6, k + 2, j + 83, 4);
        world.setBlock(i + 6, k + 2, j + 85, 37);
        world1.setBlockWithMetadata(i + 6, k + 2, j + 86, 31, 1);
        world.setBlock(i + 6, k + 2, j + 87, 37);
        world.setBlock(i + 6, k + 3, j + 18, 18);
        world.setBlock(i + 6, k + 3, j + 19, 18);
        world.setBlock(i + 6, k + 3, j + 20, 18);
        world.setBlock(i + 6, k + 3, j + 21, 18);
        world.setBlock(i + 6, k + 3, j + 22, 18);
        world.setBlock(i + 6, k + 3, j + 51, 85);
        world.setBlock(i + 6, k + 3, j + 58, 85);
        world.setBlock(i + 6, k + 3, j + 77, 67);
        world.setBlock(i + 6, k + 3, j + 78, 4);
        world.setBlock(i + 6, k + 3, j + 79, 4);
        world.setBlock(i + 6, k + 3, j + 80, 4);
        world.setBlock(i + 6, k + 3, j + 81, 4);
        world.setBlock(i + 6, k + 3, j + 82, 4);
        world.setBlock(i + 6, k + 3, j + 83, 67);
        world.setBlock(i + 6, k + 4, j + 2, 18);
        world.setBlock(i + 6, k + 4, j + 3, 18);
        world.setBlock(i + 6, k + 4, j + 4, 18);
        world.setBlock(i + 6, k + 4, j + 5, 18);
        world.setBlock(i + 6, k + 4, j + 6, 18);
        world.setBlock(i + 6, k + 4, j + 18, 18);
        world.setBlock(i + 6, k + 4, j + 19, 18);
        world.setBlock(i + 6, k + 4, j + 20, 18);
        world.setBlock(i + 6, k + 4, j + 21, 18);
        world.setBlock(i + 6, k + 4, j + 22, 18);
        world.setBlock(i + 6, k + 4, j + 51, 89);
        world.setBlock(i + 6, k + 4, j + 58, 89);
        world.setBlock(i + 6, k + 4, j + 78, 4);
        world.setBlock(i + 6, k + 4, j + 79, 4);
        world.setBlock(i + 6, k + 4, j + 80, 4);
        world.setBlock(i + 6, k + 4, j + 81, 4);
        world.setBlock(i + 6, k + 4, j + 82, 4);
        world.setBlock(i + 6, k + 5, j + 2, 18);
        world.setBlock(i + 6, k + 5, j + 3, 18);
        world.setBlock(i + 6, k + 5, j + 4, 18);
        world.setBlock(i + 6, k + 5, j + 5, 18);
        world.setBlock(i + 6, k + 5, j + 6, 18);
        world.setBlock(i + 6, k + 5, j + 19, 18);
        world.setBlock(i + 6, k + 5, j + 20, 18);
        world.setBlock(i + 6, k + 5, j + 78, 4);
        world.setBlock(i + 6, k + 5, j + 79, 4);
        world.setBlock(i + 6, k + 5, j + 80, 4);
        world.setBlock(i + 6, k + 5, j + 81, 4);
        world.setBlock(i + 6, k + 5, j + 82, 4);
        world.setBlock(i + 6, k + 6, j + 4, 18);
        world.setBlock(i + 6, k + 6, j + 20, 18);
        world.setBlock(i + 6, k + 6, j + 78, 4);
        world.setBlock(i + 6, k + 6, j + 79, 4);
        world.setBlock(i + 6, k + 6, j + 80, 4);
        world.setBlock(i + 6, k + 6, j + 81, 4);
        world.setBlock(i + 6, k + 6, j + 82, 4);
        world.setBlock(i + 6, k + 7, j + 4, 18);
        world.setBlock(i + 6, k + 7, j + 78, 4);
        world.setBlock(i + 6, k + 7, j + 79, 4);
        world.setBlock(i + 6, k + 7, j + 80, 4);
        world.setBlock(i + 6, k + 7, j + 81, 4);
        world.setBlock(i + 6, k + 7, j + 82, 4);
        world.setBlock(i + 6, k + 8, j + 78, 4);
        world.setBlock(i + 6, k + 8, j + 79, 4);
        world.setBlock(i + 6, k + 8, j + 80, 4);
        world.setBlock(i + 6, k + 8, j + 81, 4);
        world.setBlock(i + 6, k + 8, j + 82, 4);
        world.setBlock(i + 6, k + 9, j + 78, 4);
        world.setBlock(i + 6, k + 9, j + 79, 4);
        world.setBlock(i + 6, k + 9, j + 80, 4);
        world.setBlock(i + 6, k + 9, j + 81, 4);
        world.setBlock(i + 6, k + 9, j + 82, 4);
        world.setBlock(i + 6, k + 10, j + 78, 4);
        world.setBlock(i + 6, k + 10, j + 79, 4);
        world.setBlock(i + 6, k + 10, j + 80, 4);
        world.setBlock(i + 6, k + 10, j + 81, 4);
        world.setBlock(i + 6, k + 10, j + 82, 4);
        world.setBlock(i + 6, k + 11, j + 78, 4);
        world.setBlock(i + 6, k + 11, j + 79, 4);
        world.setBlock(i + 6, k + 11, j + 80, 4);
        world.setBlock(i + 6, k + 11, j + 81, 4);
        world.setBlock(i + 6, k + 11, j + 82, 4);
        world.setBlock(i + 6, k + 12, j + 78, 4);
        world.setBlock(i + 6, k + 12, j + 79, 4);
        world.setBlock(i + 6, k + 12, j + 80, 4);
        world.setBlock(i + 6, k + 12, j + 81, 4);
        world.setBlock(i + 6, k + 12, j + 82, 4);
        world.setBlock(i + 6, k + 13, j + 77, 4);
        world.setBlock(i + 6, k + 13, j + 78, 4);
        world1.setBlockWithMetadata(i + 6, k + 13, j + 79, 67, 1);
        world1.setBlockWithMetadata(i + 6, k + 13, j + 80, 67, 1);
        world1.setBlockWithMetadata(i + 6, k + 13, j + 81, 67, 1);
        world.setBlock(i + 6, k + 13, j + 82, 4);
        world.setBlock(i + 6, k + 13, j + 83, 4);
        world.setBlock(i + 6, k + 14, j + 77, 4);
        world.setBlock(i + 6, k + 14, j + 83, 4);
        world1.setBlockWithMetadata(i + 6, k + 20, j + 46, 67, 2);
        world1.setBlockWithMetadata(i + 6, k + 20, j + 54, 67, 3);
        world1.setBlockWithMetadata(i + 6, k + 20, j + 55, 67, 2);
        world1.setBlockWithMetadata(i + 6, k + 20, j + 63, 67, 3);
        world1.setBlockWithMetadata(i + 6, k + 20, j + 68, 67, 2);
        world1.setBlockWithMetadata(i + 6, k + 21, j + 47, 67, 2);
        world1.setBlockWithMetadata(i + 6, k + 21, j + 53, 67, 3);
        world1.setBlockWithMetadata(i + 6, k + 21, j + 56, 67, 2);
        world1.setBlockWithMetadata(i + 6, k + 21, j + 62, 67, 3);
        world1.setBlockWithMetadata(i + 6, k + 21, j + 69, 67, 2);
        world1.setBlockWithMetadata(i + 6, k + 22, j + 48, 67, 2);
        world1.setBlockWithMetadata(i + 6, k + 22, j + 52, 67, 3);
        world1.setBlockWithMetadata(i + 6, k + 22, j + 57, 67, 2);
        world1.setBlockWithMetadata(i + 6, k + 22, j + 61, 67, 3);
        world1.setBlockWithMetadata(i + 6, k + 22, j + 70, 67, 2);
        world1.setBlockWithMetadata(i + 6, k + 23, j + 49, 67, 2);
        world1.setBlockWithMetadata(i + 6, k + 23, j + 51, 67, 3);
        world1.setBlockWithMetadata(i + 6, k + 23, j + 58, 67, 2);
        world1.setBlockWithMetadata(i + 6, k + 23, j + 60, 67, 3);
        world1.setBlockWithMetadata(i + 6, k + 23, j + 71, 67, 2);
        world1.setBlockWithMetadata(i + 6, k + 24, j + 50, 44, 3);
        world1.setBlockWithMetadata(i + 6, k + 24, j + 59, 44, 3);
        world1.setBlockWithMetadata(i + 6, k + 24, j + 72, 44, 3);
        world.setBlock(i + 6, k + 24, j + 73, 67);
        world.setBlock(i + 6, k + 24, j + 74, 67);
        world1.setBlockWithMetadata(i + 6, k + 24, j + 75, 44, 3);
        world.setBlock(i + 7, k + 0, j + 1, 2);
        world.setBlock(i + 7, k + 0, j + 2, 2);
        world.setBlock(i + 7, k + 0, j + 3, 2);
        world.setBlock(i + 7, k + 0, j + 4, 3);
        world.setBlock(i + 7, k + 0, j + 5, 2);
        world.setBlock(i + 7, k + 0, j + 6, 2);
        world.setBlock(i + 7, k + 0, j + 7, 2);
        world.setBlock(i + 7, k + 0, j + 8, 2);
        world.setBlock(i + 7, k + 0, j + 9, 2);
        world.setBlock(i + 7, k + 0, j + 10, 3);
        world.setBlock(i + 7, k + 0, j + 11, 3);
        world.setBlock(i + 7, k + 0, j + 12, 3);
        world.setBlock(i + 7, k + 0, j + 13, 3);
        world.setBlock(i + 7, k + 0, j + 14, 3);
        world.setBlock(i + 7, k + 0, j + 15, 3);
        world.setBlock(i + 7, k + 0, j + 16, 3);
        world.setBlock(i + 7, k + 0, j + 17, 2);
        world.setBlock(i + 7, k + 0, j + 18, 2);
        world.setBlock(i + 7, k + 0, j + 19, 2);
        world.setBlock(i + 7, k + 0, j + 20, 2);
        world.setBlock(i + 7, k + 0, j + 21, 2);
        world.setBlock(i + 7, k + 0, j + 22, 2);
        world.setBlock(i + 7, k + 0, j + 23, 2);
        world.setBlock(i + 7, k + 0, j + 24, 2);
        world.setBlock(i + 7, k + 0, j + 25, 2);
        world.setBlock(i + 7, k + 0, j + 26, 2);
        world.setBlock(i + 7, k + 0, j + 27, 3);
        world.setBlock(i + 7, k + 0, j + 28, 3);
        world.setBlock(i + 7, k + 0, j + 29, 3);
        world.setBlock(i + 7, k + 0, j + 30, 3);
        world.setBlock(i + 7, k + 0, j + 31, 3);
        world.setBlock(i + 7, k + 0, j + 32, 3);
        world.setBlock(i + 7, k + 0, j + 33, 3);
        world.setBlock(i + 7, k + 0, j + 34, 3);
        world.setBlock(i + 7, k + 0, j + 35, 3);
        world.setBlock(i + 7, k + 0, j + 36, 3);
        world.setBlock(i + 7, k + 0, j + 37, 3);
        world.setBlock(i + 7, k + 0, j + 38, 3);
        world.setBlock(i + 7, k + 0, j + 39, 3);
        world.setBlock(i + 7, k + 0, j + 40, 3);
        world.setBlock(i + 7, k + 0, j + 41, 3);
        world.setBlock(i + 7, k + 0, j + 42, 3);
        world.setBlock(i + 7, k + 0, j + 43, 3);
        world.setBlock(i + 7, k + 0, j + 44, 3);
        world.setBlock(i + 7, k + 0, j + 45, 3);
        world.setBlock(i + 7, k + 0, j + 46, 3);
        world.setBlock(i + 7, k + 0, j + 47, 3);
        world.setBlock(i + 7, k + 0, j + 48, 3);
        world.setBlock(i + 7, k + 0, j + 49, 3);
        world.setBlock(i + 7, k + 0, j + 50, 3);
        world.setBlock(i + 7, k + 0, j + 51, 3);
        world.setBlock(i + 7, k + 0, j + 52, 13);
        world.setBlock(i + 7, k + 0, j + 53, 13);
        world.setBlock(i + 7, k + 0, j + 54, 13);
        world.setBlock(i + 7, k + 0, j + 55, 13);
        world.setBlock(i + 7, k + 0, j + 56, 13);
        world.setBlock(i + 7, k + 0, j + 57, 13);
        world.setBlock(i + 7, k + 0, j + 58, 3);
        world.setBlock(i + 7, k + 0, j + 59, 3);
        world.setBlock(i + 7, k + 0, j + 60, 3);
        world.setBlock(i + 7, k + 0, j + 61, 3);
        world.setBlock(i + 7, k + 0, j + 62, 3);
        world.setBlock(i + 7, k + 0, j + 63, 3);
        world.setBlock(i + 7, k + 0, j + 64, 3);
        world.setBlock(i + 7, k + 0, j + 65, 3);
        world.setBlock(i + 7, k + 0, j + 66, 3);
        world.setBlock(i + 7, k + 0, j + 67, 3);
        world.setBlock(i + 7, k + 0, j + 68, 3);
        world.setBlock(i + 7, k + 0, j + 69, 3);
        world.setBlock(i + 7, k + 0, j + 70, 3);
        world.setBlock(i + 7, k + 0, j + 71, 3);
        world.setBlock(i + 7, k + 0, j + 72, 3);
        world.setBlock(i + 7, k + 0, j + 73, 3);
        world.setBlock(i + 7, k + 0, j + 74, 3);
        world.setBlock(i + 7, k + 0, j + 75, 3);
        world.setBlock(i + 7, k + 0, j + 76, 3);
        world.setBlock(i + 7, k + 0, j + 77, 3);
        world.setBlock(i + 7, k + 0, j + 78, 3);
        world.setBlock(i + 7, k + 0, j + 79, 3);
        world.setBlock(i + 7, k + 0, j + 80, 3);
        world.setBlock(i + 7, k + 0, j + 81, 3);
        world.setBlock(i + 7, k + 0, j + 82, 3);
        world.setBlock(i + 7, k + 0, j + 83, 3);
        world.setBlock(i + 7, k + 0, j + 84, 3);
        world.setBlock(i + 7, k + 0, j + 85, 3);
        world.setBlock(i + 7, k + 0, j + 86, 3);
        world.setBlock(i + 7, k + 0, j + 87, 3);
        world.setBlock(i + 7, k + 0, j + 88, 3);
        world.setBlock(i + 7, k + 0, j + 89, 3);
        world.setBlock(i + 7, k + 0, j + 90, 2);
        world.setBlock(i + 7, k + 1, j + 4, 17);
        world.setBlock(i + 7, k + 1, j + 7, 37);
        world.setBlock(i + 7, k + 1, j + 10, 2);
        world.setBlock(i + 7, k + 1, j + 11, 2);
        world.setBlock(i + 7, k + 1, j + 12, 2);
        world.setBlock(i + 7, k + 1, j + 13, 2);
        world.setBlock(i + 7, k + 1, j + 14, 2);
        world.setBlock(i + 7, k + 1, j + 15, 2);
        world.setBlock(i + 7, k + 1, j + 16, 2);
        world1.setBlockWithMetadata(i + 7, k + 1, j + 21, 31, 1);
        world1.setBlockWithMetadata(i + 7, k + 1, j + 24, 31, 1);
        world.setBlock(i + 7, k + 1, j + 27, 2);
        world.setBlock(i + 7, k + 1, j + 28, 2);
        world.setBlock(i + 7, k + 1, j + 29, 2);
        world.setBlock(i + 7, k + 1, j + 30, 2);
        world.setBlock(i + 7, k + 1, j + 31, 2);
        world.setBlock(i + 7, k + 1, j + 32, 2);
        world.setBlock(i + 7, k + 1, j + 33, 2);
        world.setBlock(i + 7, k + 1, j + 34, 2);
        world.setBlock(i + 7, k + 1, j + 35, 2);
        world.setBlock(i + 7, k + 1, j + 36, 2);
        world.setBlock(i + 7, k + 1, j + 37, 2);
        world.setBlock(i + 7, k + 1, j + 38, 2);
        world.setBlock(i + 7, k + 1, j + 39, 2);
        world.setBlock(i + 7, k + 1, j + 40, 2);
        world.setBlock(i + 7, k + 1, j + 41, 2);
        world.setBlock(i + 7, k + 1, j + 42, 2);
        world.setBlock(i + 7, k + 1, j + 43, 2);
        world.setBlock(i + 7, k + 1, j + 44, 2);
        world.setBlock(i + 7, k + 1, j + 45, 2);
        world.setBlock(i + 7, k + 1, j + 46, 2);
        world.setBlock(i + 7, k + 1, j + 47, 2);
        world.setBlock(i + 7, k + 1, j + 48, 2);
        world.setBlock(i + 7, k + 1, j + 49, 2);
        world.setBlock(i + 7, k + 1, j + 50, 2);
        world.setBlock(i + 7, k + 1, j + 51, 2);
        world.setBlock(i + 7, k + 1, j + 52, 13);
        world.setBlock(i + 7, k + 1, j + 53, 13);
        world.setBlock(i + 7, k + 1, j + 54, 13);
        world.setBlock(i + 7, k + 1, j + 55, 13);
        world.setBlock(i + 7, k + 1, j + 56, 13);
        world.setBlock(i + 7, k + 1, j + 57, 13);
        world.setBlock(i + 7, k + 1, j + 58, 2);
        world.setBlock(i + 7, k + 1, j + 59, 2);
        world.setBlock(i + 7, k + 1, j + 60, 2);
        world.setBlock(i + 7, k + 1, j + 61, 2);
        world.setBlock(i + 7, k + 1, j + 62, 2);
        world.setBlock(i + 7, k + 1, j + 63, 2);
        world.setBlock(i + 7, k + 1, j + 64, 2);
        world.setBlock(i + 7, k + 1, j + 65, 2);
        world.setBlock(i + 7, k + 1, j + 66, 2);
        world.setBlock(i + 7, k + 1, j + 67, 2);
        world.setBlock(i + 7, k + 1, j + 68, 2);
        world.setBlock(i + 7, k + 1, j + 69, 2);
        world.setBlock(i + 7, k + 1, j + 70, 2);
        world.setBlock(i + 7, k + 1, j + 71, 2);
        world.setBlock(i + 7, k + 1, j + 72, 2);
        world.setBlock(i + 7, k + 1, j + 73, 2);
        world.setBlock(i + 7, k + 1, j + 74, 2);
        world.setBlock(i + 7, k + 1, j + 75, 2);
        world.setBlock(i + 7, k + 1, j + 76, 3);
        world.setBlock(i + 7, k + 1, j + 77, 3);
        world.setBlock(i + 7, k + 1, j + 78, 3);
        world.setBlock(i + 7, k + 1, j + 79, 3);
        world.setBlock(i + 7, k + 1, j + 80, 3);
        world.setBlock(i + 7, k + 1, j + 81, 3);
        world.setBlock(i + 7, k + 1, j + 82, 3);
        world.setBlock(i + 7, k + 1, j + 83, 3);
        world.setBlock(i + 7, k + 1, j + 84, 3);
        world.setBlock(i + 7, k + 1, j + 85, 2);
        world.setBlock(i + 7, k + 1, j + 86, 2);
        world.setBlock(i + 7, k + 1, j + 87, 2);
        world.setBlock(i + 7, k + 1, j + 88, 2);
        world.setBlock(i + 7, k + 1, j + 89, 2);
        world.setBlock(i + 7, k + 2, j + 4, 17);
        world1.setBlockWithMetadata(i + 7, k + 2, j + 10, 31, 1);
        world1.setBlockWithMetadata(i + 7, k + 2, j + 11, 31, 1);
        world.setBlock(i + 7, k + 2, j + 12, 37);
        world1.setBlockWithMetadata(i + 7, k + 2, j + 13, 31, 1);
        world1.setBlockWithMetadata(i + 7, k + 2, j + 15, 31, 1);
        world1.setBlockWithMetadata(i + 7, k + 2, j + 31, 31, 1);
        world1.setBlockWithMetadata(i + 7, k + 2, j + 32, 31, 1);
        world1.setBlockWithMetadata(i + 7, k + 2, j + 33, 31, 1);
        world1.setBlockWithMetadata(i + 7, k + 2, j + 36, 31, 1);
        world1.setBlockWithMetadata(i + 7, k + 2, j + 37, 31, 1);
        world.setBlock(i + 7, k + 2, j + 38, 37);
        world.setBlock(i + 7, k + 2, j + 39, 37);
        world1.setBlockWithMetadata(i + 7, k + 2, j + 42, 31, 1);
        world1.setBlockWithMetadata(i + 7, k + 2, j + 43, 31, 1);
        world1.setBlockWithMetadata(i + 7, k + 2, j + 49, 31, 1);
        world.setBlock(i + 7, k + 2, j + 76, 4);
        world.setBlock(i + 7, k + 2, j + 77, 4);
        world.setBlock(i + 7, k + 2, j + 78, 4);
        world.setBlock(i + 7, k + 2, j + 79, 4);
        world.setBlock(i + 7, k + 2, j + 80, 4);
        world.setBlock(i + 7, k + 2, j + 81, 4);
        world.setBlock(i + 7, k + 2, j + 82, 4);
        world.setBlock(i + 7, k + 2, j + 83, 4);
        world.setBlock(i + 7, k + 2, j + 84, 4);
        world1.setBlockWithMetadata(i + 7, k + 2, j + 85, 31, 1);
        world1.setBlockWithMetadata(i + 7, k + 2, j + 86, 31, 1);
        world1.setBlockWithMetadata(i + 7, k + 2, j + 87, 31, 1);
        world1.setBlockWithMetadata(i + 7, k + 2, j + 88, 31, 1);
        world.setBlock(i + 7, k + 3, j + 4, 17);
        world.setBlock(i + 7, k + 3, j + 18, 18);
        world.setBlock(i + 7, k + 3, j + 19, 18);
        world.setBlock(i + 7, k + 3, j + 20, 18);
        world.setBlock(i + 7, k + 3, j + 21, 18);
        world.setBlock(i + 7, k + 3, j + 27, 18);
        world.setBlock(i + 7, k + 3, j + 28, 18);
        world.setBlock(i + 7, k + 3, j + 29, 18);
        world.setBlock(i + 7, k + 3, j + 30, 18);
        world.setBlock(i + 7, k + 3, j + 76, 4);
        world.setBlock(i + 7, k + 3, j + 77, 4);
        world.setBlock(i + 7, k + 3, j + 78, 4);
        world.setBlock(i + 7, k + 3, j + 79, 4);
        world.setBlock(i + 7, k + 3, j + 80, 4);
        world.setBlock(i + 7, k + 3, j + 81, 4);
        world.setBlock(i + 7, k + 3, j + 82, 4);
        world.setBlock(i + 7, k + 3, j + 83, 4);
        world.setBlock(i + 7, k + 3, j + 84, 4);
        world.setBlock(i + 7, k + 4, j + 2, 18);
        world.setBlock(i + 7, k + 4, j + 3, 18);
        world.setBlock(i + 7, k + 4, j + 4, 17);
        world.setBlock(i + 7, k + 4, j + 5, 18);
        world.setBlock(i + 7, k + 4, j + 6, 18);
        world.setBlock(i + 7, k + 4, j + 19, 18);
        world.setBlock(i + 7, k + 4, j + 20, 18);
        world.setBlock(i + 7, k + 4, j + 21, 18);
        world.setBlock(i + 7, k + 4, j + 22, 18);
        world.setBlock(i + 7, k + 4, j + 28, 18);
        world.setBlock(i + 7, k + 4, j + 29, 18);
        world.setBlock(i + 7, k + 4, j + 30, 18);
        world.setBlock(i + 7, k + 4, j + 31, 18);
        world1.setBlockWithMetadata(i + 7, k + 4, j + 76, 67, 2);
        world.setBlock(i + 7, k + 4, j + 77, 4);
        world.setBlock(i + 7, k + 4, j + 78, 4);
        world.setBlock(i + 7, k + 4, j + 79, 4);
        world.setBlock(i + 7, k + 4, j + 80, 4);
        world.setBlock(i + 7, k + 4, j + 81, 4);
        world.setBlock(i + 7, k + 4, j + 82, 4);
        world.setBlock(i + 7, k + 4, j + 83, 4);
        world1.setBlockWithMetadata(i + 7, k + 4, j + 84, 67, 3);
        world.setBlock(i + 7, k + 5, j + 2, 18);
        world.setBlock(i + 7, k + 5, j + 3, 18);
        world.setBlock(i + 7, k + 5, j + 4, 17);
        world.setBlock(i + 7, k + 5, j + 5, 18);
        world.setBlock(i + 7, k + 5, j + 6, 18);
        world.setBlock(i + 7, k + 5, j + 77, 4);
        world.setBlock(i + 7, k + 5, j + 78, 4);
        world.setBlock(i + 7, k + 5, j + 79, 4);
        world.setBlock(i + 7, k + 5, j + 80, 4);
        world.setBlock(i + 7, k + 5, j + 81, 4);
        world.setBlock(i + 7, k + 5, j + 82, 4);
        world.setBlock(i + 7, k + 5, j + 83, 4);
        world.setBlock(i + 7, k + 6, j + 3, 18);
        world.setBlock(i + 7, k + 6, j + 4, 17);
        world.setBlock(i + 7, k + 6, j + 5, 18);
        world.setBlock(i + 7, k + 6, j + 77, 4);
        world.setBlock(i + 7, k + 6, j + 78, 4);
        world.setBlock(i + 7, k + 6, j + 79, 4);
        world.setBlock(i + 7, k + 6, j + 80, 4);
        world.setBlock(i + 7, k + 6, j + 81, 4);
        world.setBlock(i + 7, k + 6, j + 82, 4);
        world.setBlock(i + 7, k + 6, j + 83, 4);
        world.setBlock(i + 7, k + 7, j + 3, 18);
        world.setBlock(i + 7, k + 7, j + 4, 18);
        world.setBlock(i + 7, k + 7, j + 5, 18);
        world.setBlock(i + 7, k + 7, j + 77, 4);
        world.setBlock(i + 7, k + 7, j + 78, 4);
        world.setBlock(i + 7, k + 7, j + 79, 4);
        world.setBlock(i + 7, k + 7, j + 80, 4);
        world.setBlock(i + 7, k + 7, j + 81, 4);
        world.setBlock(i + 7, k + 7, j + 82, 4);
        world.setBlock(i + 7, k + 7, j + 83, 4);
        world.setBlock(i + 7, k + 8, j + 77, 4);
        world.setBlock(i + 7, k + 8, j + 78, 4);
        world.setBlock(i + 7, k + 8, j + 79, 4);
        world.setBlock(i + 7, k + 8, j + 80, 4);
        world.setBlock(i + 7, k + 8, j + 81, 4);
        world.setBlock(i + 7, k + 8, j + 82, 4);
        world.setBlock(i + 7, k + 8, j + 83, 4);
        world.setBlock(i + 7, k + 9, j + 77, 4);
        world.setBlock(i + 7, k + 9, j + 78, 4);
        world.setBlock(i + 7, k + 9, j + 79, 4);
        world.setBlock(i + 7, k + 9, j + 80, 4);
        world.setBlock(i + 7, k + 9, j + 81, 4);
        world.setBlock(i + 7, k + 9, j + 82, 4);
        world.setBlock(i + 7, k + 9, j + 83, 4);
        world.setBlock(i + 7, k + 10, j + 77, 4);
        world.setBlock(i + 7, k + 10, j + 78, 4);
        world.setBlock(i + 7, k + 10, j + 79, 4);
        world.setBlock(i + 7, k + 10, j + 80, 4);
        world.setBlock(i + 7, k + 10, j + 81, 4);
        world.setBlock(i + 7, k + 10, j + 82, 4);
        world.setBlock(i + 7, k + 10, j + 83, 4);
        world.setBlock(i + 7, k + 11, j + 77, 4);
        world.setBlock(i + 7, k + 11, j + 78, 4);
        world.setBlock(i + 7, k + 11, j + 79, 4);
        world.setBlock(i + 7, k + 11, j + 80, 4);
        world.setBlock(i + 7, k + 11, j + 81, 4);
        world.setBlock(i + 7, k + 11, j + 82, 4);
        world.setBlock(i + 7, k + 11, j + 83, 4);
        world.setBlock(i + 7, k + 12, j + 77, 4);
        world.setBlock(i + 7, k + 12, j + 78, 4);
        world.setBlock(i + 7, k + 12, j + 79, 4);
        world.setBlock(i + 7, k + 12, j + 80, 4);
        world.setBlock(i + 7, k + 12, j + 81, 4);
        world.setBlock(i + 7, k + 12, j + 82, 4);
        world.setBlock(i + 7, k + 12, j + 83, 4);
        world.setBlock(i + 7, k + 13, j + 76, 4);
        world.setBlock(i + 7, k + 13, j + 77, 4);
        world1.setBlockWithMetadata(i + 7, k + 13, j + 78, 67, 3);
        world1.setBlockWithMetadata(i + 7, k + 13, j + 82, 67, 2);
        world.setBlock(i + 7, k + 13, j + 83, 4);
        world.setBlock(i + 7, k + 13, j + 84, 4);
        world.setBlock(i + 7, k + 14, j + 76, 4);
        world.setBlock(i + 7, k + 14, j + 84, 4);
        world1.setBlockWithMetadata(i + 7, k + 15, j + 76, 67, 2);
        world1.setBlockWithMetadata(i + 7, k + 15, j + 84, 67, 3);
        world.setBlock(i + 7, k + 17, j + 47, 17);
        world.setBlock(i + 7, k + 17, j + 48, 53);
        world.setBlock(i + 7, k + 17, j + 49, 53);
        world.setBlock(i + 7, k + 17, j + 50, 17);
        world.setBlock(i + 7, k + 17, j + 51, 53);
        world.setBlock(i + 7, k + 17, j + 52, 53);
        world.setBlock(i + 7, k + 17, j + 53, 17);
        world.setBlock(i + 7, k + 17, j + 56, 17);
        world.setBlock(i + 7, k + 17, j + 57, 53);
        world.setBlock(i + 7, k + 17, j + 58, 53);
        world.setBlock(i + 7, k + 17, j + 59, 17);
        world.setBlock(i + 7, k + 17, j + 60, 53);
        world.setBlock(i + 7, k + 17, j + 61, 53);
        world.setBlock(i + 7, k + 17, j + 62, 17);
        world.setBlock(i + 7, k + 17, j + 69, 17);
        world.setBlock(i + 7, k + 17, j + 70, 17);
        world.setBlock(i + 7, k + 17, j + 71, 17);
        world.setBlock(i + 7, k + 17, j + 72, 17);
        world.setBlock(i + 7, k + 17, j + 73, 17);
        world.setBlock(i + 7, k + 18, j + 47, 17);
        world.setBlock(i + 7, k + 18, j + 48, 53);
        world.setBlock(i + 7, k + 18, j + 49, 53);
        world.setBlock(i + 7, k + 18, j + 50, 17);
        world.setBlock(i + 7, k + 18, j + 51, 53);
        world.setBlock(i + 7, k + 18, j + 52, 53);
        world.setBlock(i + 7, k + 18, j + 53, 17);
        world.setBlock(i + 7, k + 18, j + 56, 17);
        world.setBlock(i + 7, k + 18, j + 57, 53);
        world.setBlock(i + 7, k + 18, j + 58, 53);
        world.setBlock(i + 7, k + 18, j + 59, 17);
        world.setBlock(i + 7, k + 18, j + 60, 53);
        world.setBlock(i + 7, k + 18, j + 61, 53);
        world.setBlock(i + 7, k + 18, j + 62, 17);
        world.setBlock(i + 7, k + 18, j + 69, 17);
        world.setBlock(i + 7, k + 18, j + 70, 53);
        world.setBlock(i + 7, k + 18, j + 71, 5);
        world.setBlock(i + 7, k + 18, j + 72, 5);
        world.setBlock(i + 7, k + 18, j + 73, 17);
        world.setBlock(i + 7, k + 18, j + 74, 17);
        world.setBlock(i + 7, k + 19, j + 47, 17);
        world.setBlock(i + 7, k + 19, j + 48, 102);
        world.setBlock(i + 7, k + 19, j + 49, 102);
        world.setBlock(i + 7, k + 19, j + 50, 17);
        world.setBlock(i + 7, k + 19, j + 51, 102);
        world.setBlock(i + 7, k + 19, j + 52, 102);
        world.setBlock(i + 7, k + 19, j + 53, 17);
        world.setBlock(i + 7, k + 19, j + 56, 17);
        world.setBlock(i + 7, k + 19, j + 57, 102);
        world.setBlock(i + 7, k + 19, j + 58, 102);
        world.setBlock(i + 7, k + 19, j + 59, 17);
        world.setBlock(i + 7, k + 19, j + 60, 102);
        world.setBlock(i + 7, k + 19, j + 61, 102);
        world.setBlock(i + 7, k + 19, j + 62, 17);
        world.setBlock(i + 7, k + 19, j + 69, 17);
        world.setBlock(i + 7, k + 19, j + 70, 102);
        world.setBlock(i + 7, k + 19, j + 71, 5);
        world.setBlock(i + 7, k + 19, j + 72, 53);
        world.setBlock(i + 7, k + 19, j + 73, 53);
        world.setBlock(i + 7, k + 19, j + 74, 17);
        world1.setBlockWithMetadata(i + 7, k + 20, j + 46, 67, 2);
        world.setBlock(i + 7, k + 20, j + 47, 17);
        world.setBlock(i + 7, k + 20, j + 48, 102);
        world.setBlock(i + 7, k + 20, j + 49, 102);
        world.setBlock(i + 7, k + 20, j + 50, 17);
        world.setBlock(i + 7, k + 20, j + 51, 102);
        world.setBlock(i + 7, k + 20, j + 52, 102);
        world.setBlock(i + 7, k + 20, j + 53, 17);
        world1.setBlockWithMetadata(i + 7, k + 20, j + 54, 67, 3);
        world1.setBlockWithMetadata(i + 7, k + 20, j + 55, 67, 2);
        world.setBlock(i + 7, k + 20, j + 56, 17);
        world.setBlock(i + 7, k + 20, j + 57, 102);
        world.setBlock(i + 7, k + 20, j + 58, 102);
        world.setBlock(i + 7, k + 20, j + 59, 17);
        world.setBlock(i + 7, k + 20, j + 60, 102);
        world.setBlock(i + 7, k + 20, j + 61, 102);
        world.setBlock(i + 7, k + 20, j + 62, 17);
        world1.setBlockWithMetadata(i + 7, k + 20, j + 63, 67, 3);
        world1.setBlockWithMetadata(i + 7, k + 20, j + 68, 67, 2);
        world.setBlock(i + 7, k + 20, j + 69, 17);
        world.setBlock(i + 7, k + 20, j + 70, 102);
        world.setBlock(i + 7, k + 20, j + 71, 5);
        world.setBlock(i + 7, k + 20, j + 72, 102);
        world.setBlock(i + 7, k + 20, j + 73, 102);
        world.setBlock(i + 7, k + 20, j + 74, 17);
        world1.setBlockWithMetadata(i + 7, k + 21, j + 47, 67, 2);
        world.setBlock(i + 7, k + 21, j + 48, 17);
        world.setBlock(i + 7, k + 21, j + 49, 5);
        world.setBlock(i + 7, k + 21, j + 50, 17);
        world.setBlock(i + 7, k + 21, j + 51, 5);
        world.setBlock(i + 7, k + 21, j + 52, 17);
        world1.setBlockWithMetadata(i + 7, k + 21, j + 53, 67, 3);
        world1.setBlockWithMetadata(i + 7, k + 21, j + 56, 67, 2);
        world.setBlock(i + 7, k + 21, j + 57, 17);
        world.setBlock(i + 7, k + 21, j + 58, 5);
        world.setBlock(i + 7, k + 21, j + 59, 17);
        world.setBlock(i + 7, k + 21, j + 60, 5);
        world.setBlock(i + 7, k + 21, j + 61, 17);
        world1.setBlockWithMetadata(i + 7, k + 21, j + 62, 67, 3);
        world1.setBlockWithMetadata(i + 7, k + 21, j + 69, 67, 2);
        world.setBlock(i + 7, k + 21, j + 70, 17);
        world.setBlock(i + 7, k + 21, j + 71, 5);
        world.setBlock(i + 7, k + 21, j + 72, 102);
        world.setBlock(i + 7, k + 21, j + 73, 102);
        world.setBlock(i + 7, k + 21, j + 74, 17);
        world1.setBlockWithMetadata(i + 7, k + 22, j + 48, 67, 2);
        world.setBlock(i + 7, k + 22, j + 49, 17);
        world.setBlock(i + 7, k + 22, j + 50, 17);
    }

    private void createPart1()
    {
        world.setBlock(i + 7, k + 22, j + 51, 17);
        world1.setBlockWithMetadata(i + 7, k + 22, j + 52, 67, 3);
        world1.setBlockWithMetadata(i + 7, k + 22, j + 57, 67, 2);
        world.setBlock(i + 7, k + 22, j + 58, 17);
        world.setBlock(i + 7, k + 22, j + 59, 17);
        world.setBlock(i + 7, k + 22, j + 60, 17);
        world1.setBlockWithMetadata(i + 7, k + 22, j + 61, 67, 3);
        world1.setBlockWithMetadata(i + 7, k + 22, j + 70, 67, 2);
        world.setBlock(i + 7, k + 22, j + 71, 17);
        world.setBlock(i + 7, k + 22, j + 72, 5);
        world.setBlock(i + 7, k + 22, j + 73, 5);
        world.setBlock(i + 7, k + 22, j + 74, 17);
        world1.setBlockWithMetadata(i + 7, k + 23, j + 49, 67, 2);
        world.setBlock(i + 7, k + 23, j + 50, 17);
        world1.setBlockWithMetadata(i + 7, k + 23, j + 51, 67, 3);
        world1.setBlockWithMetadata(i + 7, k + 23, j + 58, 67, 2);
        world.setBlock(i + 7, k + 23, j + 59, 17);
        world1.setBlockWithMetadata(i + 7, k + 23, j + 60, 67, 3);
        world1.setBlockWithMetadata(i + 7, k + 23, j + 71, 67, 2);
        world.setBlock(i + 7, k + 23, j + 72, 17);
        world.setBlock(i + 7, k + 23, j + 73, 17);
        world.setBlock(i + 7, k + 23, j + 74, 17);
        world1.setBlockWithMetadata(i + 7, k + 24, j + 50, 44, 3);
        world1.setBlockWithMetadata(i + 7, k + 24, j + 59, 44, 3);
        world1.setBlockWithMetadata(i + 7, k + 24, j + 72, 67, 2);
        world.setBlock(i + 7, k + 24, j + 73, 4);
        world.setBlock(i + 7, k + 24, j + 74, 4);
        world1.setBlockWithMetadata(i + 7, k + 24, j + 75, 67, 3);
        world1.setBlockWithMetadata(i + 7, k + 25, j + 73, 44, 3);
        world1.setBlockWithMetadata(i + 7, k + 25, j + 74, 44, 3);
        world.setBlock(i + 8, k + 0, j + 1, 2);
        world.setBlock(i + 8, k + 0, j + 2, 2);
        world.setBlock(i + 8, k + 0, j + 3, 2);
        world.setBlock(i + 8, k + 0, j + 4, 2);
        world.setBlock(i + 8, k + 0, j + 5, 2);
        world.setBlock(i + 8, k + 0, j + 6, 2);
        world.setBlock(i + 8, k + 0, j + 7, 2);
        world.setBlock(i + 8, k + 0, j + 8, 2);
        world.setBlock(i + 8, k + 0, j + 9, 2);
        world.setBlock(i + 8, k + 0, j + 10, 3);
        world.setBlock(i + 8, k + 0, j + 11, 3);
        world.setBlock(i + 8, k + 0, j + 12, 3);
        world.setBlock(i + 8, k + 0, j + 13, 3);
        world.setBlock(i + 8, k + 0, j + 14, 3);
        world.setBlock(i + 8, k + 0, j + 15, 3);
        world.setBlock(i + 8, k + 0, j + 16, 3);
        world.setBlock(i + 8, k + 0, j + 17, 3);
        world.setBlock(i + 8, k + 0, j + 18, 2);
        world.setBlock(i + 8, k + 0, j + 19, 2);
        world.setBlock(i + 8, k + 0, j + 20, 2);
        world.setBlock(i + 8, k + 0, j + 21, 2);
        world.setBlock(i + 8, k + 0, j + 22, 2);
        world.setBlock(i + 8, k + 0, j + 23, 2);
        world.setBlock(i + 8, k + 0, j + 24, 2);
        world.setBlock(i + 8, k + 0, j + 25, 2);
        world.setBlock(i + 8, k + 0, j + 26, 3);
        world.setBlock(i + 8, k + 0, j + 27, 3);
        world.setBlock(i + 8, k + 0, j + 28, 3);
        world.setBlock(i + 8, k + 0, j + 29, 3);
        world.setBlock(i + 8, k + 0, j + 30, 3);
        world.setBlock(i + 8, k + 0, j + 31, 3);
        world.setBlock(i + 8, k + 0, j + 32, 3);
        world.setBlock(i + 8, k + 0, j + 33, 3);
        world.setBlock(i + 8, k + 0, j + 34, 3);
        world.setBlock(i + 8, k + 0, j + 35, 3);
        world.setBlock(i + 8, k + 0, j + 36, 3);
        world.setBlock(i + 8, k + 0, j + 37, 3);
        world.setBlock(i + 8, k + 0, j + 38, 3);
        world.setBlock(i + 8, k + 0, j + 39, 3);
        world.setBlock(i + 8, k + 0, j + 40, 3);
        world.setBlock(i + 8, k + 0, j + 41, 3);
        world.setBlock(i + 8, k + 0, j + 42, 3);
        world.setBlock(i + 8, k + 0, j + 43, 3);
        world.setBlock(i + 8, k + 0, j + 44, 3);
        world.setBlock(i + 8, k + 0, j + 45, 3);
        world.setBlock(i + 8, k + 0, j + 46, 3);
        world.setBlock(i + 8, k + 0, j + 47, 3);
        world.setBlock(i + 8, k + 0, j + 48, 3);
        world.setBlock(i + 8, k + 0, j + 49, 3);
        world.setBlock(i + 8, k + 0, j + 50, 3);
        world.setBlock(i + 8, k + 0, j + 51, 3);
        world.setBlock(i + 8, k + 0, j + 52, 13);
        world.setBlock(i + 8, k + 0, j + 53, 13);
        world.setBlock(i + 8, k + 0, j + 54, 13);
        world.setBlock(i + 8, k + 0, j + 55, 13);
        world.setBlock(i + 8, k + 0, j + 56, 13);
        world.setBlock(i + 8, k + 0, j + 57, 13);
        world.setBlock(i + 8, k + 0, j + 58, 3);
        world.setBlock(i + 8, k + 0, j + 59, 3);
        world.setBlock(i + 8, k + 0, j + 60, 3);
        world.setBlock(i + 8, k + 0, j + 61, 3);
