package aginsun.journey.universal.worldgen;

import net.minecraft.entity.EntityLiving;
import net.minecraft.world.World;
import aginsun.journey.universal.entities.EntityGuildMaster;

public class WorldGenStart 
{
	World world;
	int i,j,k;
	
	public WorldGenStart(World world, int i, int j, int k)
	{
		this.world = world;
		this.i = i;
		this.j = j;
		this.k = k;
	}

	public boolean createPart1()
	{
        world.setBlock(i + 0, j + 0, k + 7, 13);
        world.setBlock(i + 0, j + 0, k + 6, 3);
        world.setBlock(i + 0, j + 0, k + 5, 3);
        world.setBlock(i + 0, j + 0, k + 4, 3);
        world.setBlock(i + 0, j + 0, k + 3, 3);
        world.setBlock(i + 0, j + 0, k + 2, 3);
        world.setBlock(i + 0, j + 0, k + 1, 3);
        world.setBlock(i + 0, j + 0, k + 0, 3);
        world.setBlock(i + 1, j + 0, k + 7, 13);
        world.setBlock(i + 1, j + 0, k + 6, 3);
        world.setBlock(i + 1, j + 0, k + 5, 3);
        world.setBlock(i + 1, j + 0, k + 4, 3);
        world.setBlock(i + 1, j + 0, k + 3, 3);
        world.setBlock(i + 1, j + 0, k + 2, 3);
        world.setBlock(i + 1, j + 0, k + 1, 3);
        world.setBlock(i + 1, j + 0, k + 0, 3);
        world.setBlock(i + 2, j + 0, k + 7, 13);
        world.setBlock(i + 2, j + 0, k + 6, 3);
        world.setBlock(i + 2, j + 0, k + 5, 3);
        world.setBlock(i + 2, j + 0, k + 4, 3);
        world.setBlock(i + 2, j + 0, k + 3, 3);
        world.setBlock(i + 2, j + 0, k + 2, 3);
        world.setBlock(i + 2, j + 0, k + 1, 3);
        world.setBlock(i + 2, j + 0, k + 0, 3);
        world.setBlock(i + 3, j + 0, k + 7, 13);
        world.setBlock(i + 3, j + 0, k + 6, 3);
        world.setBlock(i + 3, j + 0, k + 5, 3);
        world.setBlock(i + 3, j + 0, k + 4, 3);
        world.setBlock(i + 3, j + 0, k + 3, 3);
        world.setBlock(i + 3, j + 0, k + 2, 3);
        world.setBlock(i + 3, j + 0, k + 1, 3);
        world.setBlock(i + 3, j + 0, k + 0, 3);
        world.setBlock(i + 4, j + 0, k + 7, 13);
        world.setBlock(i + 4, j + 0, k + 6, 3);
        world.setBlock(i + 4, j + 0, k + 5, 3);
        world.setBlock(i + 4, j + 0, k + 4, 3);
        world.setBlock(i + 4, j + 0, k + 3, 3);
        world.setBlock(i + 4, j + 0, k + 2, 3);
        world.setBlock(i + 4, j + 0, k + 1, 3);
        world.setBlock(i + 4, j + 0, k + 0, 3);
        world.setBlock(i + 5, j + 0, k + 7, 13);
        world.setBlock(i + 5, j + 0, k + 6, 3);
        world.setBlock(i + 5, j + 0, k + 5, 3);
        world.setBlock(i + 5, j + 0, k + 4, 3);
        world.setBlock(i + 5, j + 0, k + 3, 3);
        world.setBlock(i + 5, j + 0, k + 2, 3);
        world.setBlock(i + 5, j + 0, k + 1, 3);
        world.setBlock(i + 5, j + 0, k + 0, 3);
        world.setBlock(i + 6, j + 0, k + 7, 13);
        world.setBlock(i + 6, j + 0, k + 6, 3);
        world.setBlock(i + 6, j + 0, k + 5, 3);
        world.setBlock(i + 6, j + 0, k + 4, 3);
        world.setBlock(i + 6, j + 0, k + 3, 3);
        world.setBlock(i + 6, j + 0, k + 2, 3);
        world.setBlock(i + 6, j + 0, k + 1, 3);
        world.setBlock(i + 6, j + 0, k + 0, 3);
        world.setBlock(i + 7, j + 0, k + 7, 13);
        world.setBlock(i + 7, j + 0, k + 6, 3);
        world.setBlock(i + 7, j + 0, k + 5, 3);
        world.setBlock(i + 7, j + 0, k + 4, 3);
        world.setBlock(i + 7, j + 0, k + 3, 3);
        world.setBlock(i + 7, j + 0, k + 2, 3);
        world.setBlock(i + 7, j + 0, k + 1, 3);
        world.setBlock(i + 7, j + 0, k + 0, 3);
        world.setBlock(i + 8, j + 0, k + 7, 13);
        world.setBlock(i + 8, j + 0, k + 6, 3);
        world.setBlock(i + 8, j + 0, k + 5, 3);
        world.setBlock(i + 8, j + 0, k + 4, 3);
        world.setBlock(i + 8, j + 0, k + 3, 3);
        world.setBlock(i + 8, j + 0, k + 2, 3);
        world.setBlock(i + 8, j + 0, k + 1, 3);
        world.setBlock(i + 8, j + 0, k + 0, 3);
        world.setBlock(i + 9, j + 0, k + 7, 13);
        world.setBlock(i + 9, j + 0, k + 6, 3);
        world.setBlock(i + 9, j + 0, k + 5, 3);
        world.setBlock(i + 9, j + 0, k + 4, 3);
        world.setBlock(i + 9, j + 0, k + 3, 3);
        world.setBlock(i + 9, j + 0, k + 2, 3);
        world.setBlock(i + 9, j + 0, k + 1, 3);
        world.setBlock(i + 9, j + 0, k + 0, 3);
        world.setBlock(i + 0, j + 1, k + 6, 4);
        world.setBlock(i + 0, j + 1, k + 5, 4);
        world.setBlock(i + 0, j + 1, k + 4, 4);
        world.setBlock(i + 0, j + 1, k + 3, 4);
        world.setBlock(i + 0, j + 1, k + 2, 4);
        world.setBlock(i + 0, j + 1, k + 1, 4);
        world.setBlock(i + 0, j + 1, k + 0, 4);
        world.setBlock(i + 1, j + 1, k + 6, 4);
        world.setBlock(i + 1, j + 1, k + 5, 43);
        world.setBlock(i + 1, j + 1, k + 4, 43);
        world.setBlock(i + 1, j + 1, k + 3, 43);
        world.setBlock(i + 1, j + 1, k + 2, 43);
        world.setBlock(i + 1, j + 1, k + 1, 43);
        world.setBlock(i + 1, j + 1, k + 0, 4);
        world.setBlock(i + 2, j + 1, k + 6, 4);
        world.setBlock(i + 2, j + 1, k + 5, 43);
        world.setBlock(i + 2, j + 1, k + 4, 43);
        world.setBlock(i + 2, j + 1, k + 3, 43);
        world.setBlock(i + 2, j + 1, k + 2, 43);
        world.setBlock(i + 2, j + 1, k + 1, 43);
        world.setBlock(i + 2, j + 1, k + 0, 4);
        world.setBlock(i + 3, j + 1, k + 6, 4);
        world.setBlock(i + 3, j + 1, k + 5, 43);
        world.setBlock(i + 3, j + 1, k + 4, 4);
        world.setBlock(i + 3, j + 1, k + 3, 43);
        world.setBlock(i + 3, j + 1, k + 2, 43);
        world.setBlock(i + 3, j + 1, k + 1, 43);
        world.setBlock(i + 3, j + 1, k + 0, 4);
        world.setBlock(i + 4, j + 1, k + 6, 4);
        world.setBlock(i + 4, j + 1, k + 5, 4);
        world.setBlock(i + 4, j + 1, k + 4, 4);
        world.setBlock(i + 4, j + 1, k + 3, 4);
        world.setBlock(i + 4, j + 1, k + 2, 43);
        world.setBlock(i + 4, j + 1, k + 1, 4);
        world.setBlock(i + 4, j + 1, k + 0, 4);
        world.setBlock(i + 5, j + 1, k + 6, 4);
        world.setBlock(i + 5, j + 1, k + 5, 4);
        world.setBlock(i + 5, j + 1, k + 4, 4);
        world.setBlock(i + 5, j + 1, k + 3, 4);
        world.setBlock(i + 5, j + 1, k + 2, 4);
        world.setBlock(i + 5, j + 1, k + 1, 4);
        world.setBlock(i + 5, j + 1, k + 0, 4);
        world.setBlock(i + 6, j + 1, k + 7, 67);
        world.setBlock(i + 6, j + 1, k + 6, 4);
        world.setBlock(i + 6, j + 1, k + 5, 4);
        world.setBlock(i + 6, j + 1, k + 4, 4);
        world.setBlock(i + 6, j + 1, k + 3, 4);
        world.setBlock(i + 6, j + 1, k + 2, 4);
        world.setBlock(i + 6, j + 1, k + 1, 4);
        world.setBlock(i + 6, j + 1, k + 0, 4);
        world.setBlock(i + 7, j + 1, k + 7, 67);
        world.setBlock(i + 7, j + 1, k + 6, 4);
        world.setBlock(i + 7, j + 1, k + 5, 4);
        world.setBlock(i + 7, j + 1, k + 4, 4);
        world.setBlock(i + 7, j + 1, k + 3, 4);
        world.setBlock(i + 7, j + 1, k + 2, 4);
        world.setBlock(i + 7, j + 1, k + 1, 4);
        world.setBlock(i + 7, j + 1, k + 0, 4);
        world.setBlock(i + 8, j + 1, k + 7, 67);
        world.setBlock(i + 8, j + 1, k + 6, 4);
        world.setBlock(i + 8, j + 1, k + 5, 4);
        world.setBlock(i + 8, j + 1, k + 4, 4);
        world.setBlock(i + 8, j + 1, k + 3, 4);
        world.setBlock(i + 8, j + 1, k + 2, 4);
        world.setBlock(i + 8, j + 1, k + 1, 4);
        world.setBlock(i + 8, j + 1, k + 0, 4);
        world.setBlock(i + 9, j + 1, k + 6, 4);
        world.setBlock(i + 9, j + 1, k + 5, 4);
        world.setBlock(i + 9, j + 1, k + 4, 4);
        world.setBlock(i + 9, j + 1, k + 3, 4);
        world.setBlock(i + 9, j + 1, k + 2, 4);
        world.setBlock(i + 9, j + 1, k + 1, 4);
        world.setBlock(i + 9, j + 1, k + 0, 4);
        world.setBlock(i + 0, j + 2, k + 6, 17);
        world.setBlock(i + 0, j + 2, k + 5, 4);
        world.setBlock(i + 0, j + 2, k + 4, 4);
        world.setBlock(i + 0, j + 2, k + 3, 4);
        world.setBlock(i + 0, j + 2, k + 2, 4);
        world.setBlock(i + 0, j + 2, k + 1, 4);
        world.setBlock(i + 0, j + 2, k + 0, 17);
        world.setBlock(i + 1, j + 2, k + 6, 4);
        world.setBlock(i + 1, j + 2, k + 0, 4);
        world.setBlock(i + 2, j + 2, k + 6, 4);
        world.setBlock(i + 2, j + 2, k + 0, 4);
        world.setBlock(i + 3, j + 2, k + 6, 17);
        world.setBlock(i + 3, j + 2, k + 5, 64);
        world.setBlock(i + 3, j + 2, k + 4, 5);
        world.setBlock(i + 3, j + 2, k + 0, 4);
        world.setBlock(i + 4, j + 2, k + 3, 5);
        world.setBlock(i + 4, j + 2, k + 2, 85);
        world.setBlock(i + 4, j + 2, k + 1, 53);
        world.setBlock(i + 4, j + 2, k + 0, 4);
        world.setBlock(i + 5, j + 2, k + 6, 85);
        world.setBlock(i + 5, j + 2, k + 3, 5);
        world.setBlock(i + 5, j + 2, k + 2, 53);
        world.setBlock(i + 5, j + 2, k + 1, 53);
        world.setBlock(i + 5, j + 2, k + 0, 4);
        world.setBlock(i + 6, j + 2, k + 3, 4);
        world.setBlock(i + 6, j + 2, k + 2, 4);
        world.setBlock(i + 6, j + 2, k + 1, 4);
        world.setBlock(i + 6, j + 2, k + 0, 4);
        world.setBlock(i + 7, j + 2, k + 2, 4);
        world.setBlock(i + 7, j + 2, k + 1, 11);
        world.setBlock(i + 7, j + 2, k + 0, 4);
        world.setBlock(i + 8, j + 2, k + 5, 43);
        world.setBlock(i + 8, j + 2, k + 2, 4);
        world.setBlock(i + 8, j + 2, k + 1, 11);
        world.setBlock(i + 8, j + 2, k + 0, 4);
        world.setBlock(i + 9, j + 2, k + 6, 85);
        world.setBlock(i + 9, j + 2, k + 2, 4);
        world.setBlock(i + 9, j + 2, k + 1, 4);
        world.setBlock(i + 9, j + 2, k + 0, 4);
        world.setBlock(i + 0, j + 3, k + 6, 17);
        world.setBlock(i + 0, j + 3, k + 5, 4);
        world.setBlock(i + 0, j + 3, k + 4, 102);
        world.setBlock(i + 0, j + 3, k + 3, 4);
        world.setBlock(i + 0, j + 3, k + 2, 102);
        world.setBlock(i + 0, j + 3, k + 1, 4);
        world.setBlock(i + 0, j + 3, k + 0, 17);
        world.setBlock(i + 1, j + 3, k + 6, 4);
        world.setBlock(i + 1, j + 3, k + 0, 4);
        world.setBlock(i + 2, j + 3, k + 6, 4);
        world.setBlock(i + 2, j + 3, k + 4, 143);
        world.setBlock(i + 2, j + 3, k + 0, 102);
        world.setBlock(i + 3, j + 3, k + 6, 17);
        world.setBlock(i + 3, j + 3, k + 5, 64);
        world.setBlock(i + 3, j + 3, k + 4, 5);
        world.setBlock(i + 3, j + 3, k + 0, 4);
        world.setBlock(i + 4, j + 3, k + 6, 50);
        world.setBlock(i + 4, j + 3, k + 4, 143);
        world.setBlock(i + 4, j + 3, k + 3, 5);
        world.setBlock(i + 4, j + 3, k + 2, 72);
        world.setBlock(i + 4, j + 3, k + 0, 102);
        world.setBlock(i + 5, j + 3, k + 6, 85);
        world.setBlock(i + 5, j + 3, k + 3, 5);
        world.setBlock(i + 5, j + 3, k + 0, 4);
        world.setBlock(i + 6, j + 3, k + 3, 4);
        world.setBlock(i + 6, j + 3, k + 2, 4);
        world.setBlock(i + 6, j + 3, k + 1, 4);
        world.setBlock(i + 6, j + 3, k + 0, 4);
        world.setBlock(i + 7, j + 3, k + 2, 101);
        world.setBlock(i + 7, j + 3, k + 0, 4);
        world.setBlock(i + 8, j + 3, k + 2, 101);
        world.setBlock(i + 8, j + 3, k + 0, 4);
        world.setBlock(i + 9, j + 3, k + 6, 85);
        world.setBlock(i + 9, j + 3, k + 2, 101);
        world.setBlock(i + 9, j + 3, k + 1, 101);
        world.setBlock(i + 9, j + 3, k + 0, 4);
        world.setBlock(i + 0, j + 4, k + 6, 17);
        world.setBlock(i + 0, j + 4, k + 5, 4);
        world.setBlock(i + 0, j + 4, k + 4, 4);
        world.setBlock(i + 0, j + 4, k + 3, 4);
        world.setBlock(i + 0, j + 4, k + 2, 4);
        world.setBlock(i + 0, j + 4, k + 1, 4);
        world.setBlock(i + 0, j + 4, k + 0, 17);
        world.setBlock(i + 1, j + 4, k + 6, 4);
        world.setBlock(i + 1, j + 4, k + 1, 50);
        world.setBlock(i + 1, j + 4, k + 0, 4);
        world.setBlock(i + 2, j + 4, k + 6, 4);
        world.setBlock(i + 2, j + 4, k + 0, 4);
        world.setBlock(i + 3, j + 4, k + 6, 17);
        world.setBlock(i + 3, j + 4, k + 5, 5);
        world.setBlock(i + 3, j + 4, k + 4, 5);
        world.setBlock(i + 3, j + 4, k + 0, 4);
        world.setBlock(i + 4, j + 4, k + 3, 5);
        world.setBlock(i + 4, j + 4, k + 0, 4);
        world.setBlock(i + 5, j + 4, k + 6, 85);
        world.setBlock(i + 5, j + 4, k + 3, 5);
        world.setBlock(i + 5, j + 4, k + 1, 50);
        world.setBlock(i + 5, j + 4, k + 0, 4);
        world.setBlock(i + 6, j + 4, k + 3, 4);
        world.setBlock(i + 6, j + 4, k + 2, 4);
        world.setBlock(i + 6, j + 4, k + 1, 4);
        world.setBlock(i + 6, j + 4, k + 0, 4);
        world.setBlock(i + 7, j + 4, k + 2, 4);
        world.setBlock(i + 7, j + 4, k + 1, 4);
        world.setBlock(i + 7, j + 4, k + 0, 4);
        world.setBlock(i + 8, j + 4, k + 2, 4);
        world.setBlock(i + 8, j + 4, k + 1, 4);
        world.setBlock(i + 8, j + 4, k + 0, 4);
        world.setBlock(i + 9, j + 4, k + 6, 85);
        world.setBlock(i + 9, j + 4, k + 2, 4);
        world.setBlock(i + 9, j + 4, k + 1, 4);
        world.setBlock(i + 9, j + 4, k + 0, 4);
        world.setBlock(i + 0, j + 5, k + 6, 17);
        world.setBlock(i + 0, j + 5, k + 5, 4);
        world.setBlock(i + 0, j + 5, k + 4, 4);
        world.setBlock(i + 0, j + 5, k + 3, 4);
        world.setBlock(i + 0, j + 5, k + 2, 4);
        world.setBlock(i + 0, j + 5, k + 1, 4);
        world.setBlock(i + 0, j + 5, k + 0, 17);
        world.setBlock(i + 1, j + 5, k + 6, 4);
        world.setBlock(i + 1, j + 5, k + 5, 4);
        world.setBlock(i + 1, j + 5, k + 4, 4);
        world.setBlock(i + 1, j + 5, k + 3, 4);
        world.setBlock(i + 1, j + 5, k + 2, 4);
        world.setBlock(i + 1, j + 5, k + 1, 4);
        world.setBlock(i + 1, j + 5, k + 0, 4);
        world.setBlock(i + 2, j + 5, k + 6, 4);
        world.setBlock(i + 2, j + 5, k + 5, 4);
        world.setBlock(i + 2, j + 5, k + 4, 4);
        world.setBlock(i + 2, j + 5, k + 3, 4);
        world.setBlock(i + 2, j + 5, k + 2, 4);
        world.setBlock(i + 2, j + 5, k + 1, 4);
        world.setBlock(i + 2, j + 5, k + 0, 4);
        world.setBlock(i + 3, j + 5, k + 6, 17);
        world.setBlock(i + 3, j + 5, k + 5, 4);
        world.setBlock(i + 3, j + 5, k + 4, 4);
        world.setBlock(i + 3, j + 5, k + 3, 4);
        world.setBlock(i + 3, j + 5, k + 2, 4);
        world.setBlock(i + 3, j + 5, k + 1, 4);
        world.setBlock(i + 3, j + 5, k + 0, 4);
        world.setBlock(i + 4, j + 5, k + 6, 4);
        world.setBlock(i + 4, j + 5, k + 5, 4);
        world.setBlock(i + 4, j + 5, k + 4, 4);
        world.setBlock(i + 4, j + 5, k + 3, 4);
        world.setBlock(i + 4, j + 5, k + 2, 4);
        world.setBlock(i + 4, j + 5, k + 1, 4);
        world.setBlock(i + 4, j + 5, k + 0, 4);
        world.setBlock(i + 5, j + 5, k + 6, 4);
        world.setBlock(i + 5, j + 5, k + 5, 4);
        world.setBlock(i + 5, j + 5, k + 4, 4);
        world.setBlock(i + 5, j + 5, k + 3, 4);
        world.setBlock(i + 5, j + 5, k + 2, 4);
        world.setBlock(i + 5, j + 5, k + 1, 4);
        world.setBlock(i + 5, j + 5, k + 0, 4);
        world.setBlock(i + 6, j + 5, k + 6, 4);
        world.setBlock(i + 6, j + 5, k + 5, 4);
        world.setBlock(i + 6, j + 5, k + 4, 4);
        world.setBlock(i + 6, j + 5, k + 3, 4);
        world.setBlock(i + 6, j + 5, k + 2, 4);
        world.setBlock(i + 6, j + 5, k + 1, 4);
        world.setBlock(i + 6, j + 5, k + 0, 4);
        world.setBlock(i + 7, j + 5, k + 6, 4);
        world.setBlock(i + 7, j + 5, k + 5, 4);
        world.setBlock(i + 7, j + 5, k + 4, 4);
        world.setBlock(i + 7, j + 5, k + 3, 4);
        world.setBlock(i + 7, j + 5, k + 2, 4);
        world.setBlock(i + 7, j + 5, k + 1, 4);
        world.setBlock(i + 7, j + 5, k + 0, 4);
        world.setBlock(i + 8, j + 5, k + 6, 4);
        world.setBlock(i + 8, j + 5, k + 5, 4);
        world.setBlock(i + 8, j + 5, k + 4, 4);
        world.setBlock(i + 8, j + 5, k + 3, 4);
        world.setBlock(i + 8, j + 5, k + 2, 4);
        world.setBlock(i + 8, j + 5, k + 1, 4);
        world.setBlock(i + 8, j + 5, k + 0, 4);
        world.setBlock(i + 9, j + 5, k + 6, 4);
        world.setBlock(i + 9, j + 5, k + 5, 4);
        world.setBlock(i + 9, j + 5, k + 4, 4);
        world.setBlock(i + 9, j + 5, k + 3, 4);
        world.setBlock(i + 9, j + 5, k + 2, 4);
        world.setBlock(i + 9, j + 5, k + 1, 4);
        world.setBlock(i + 9, j + 5, k + 0, 4);
        world.setBlock(i + 0, j + 6, k + 6, 53);
        world.setBlock(i + 0, j + 6, k + 5, 5);
        world.setBlock(i + 0, j + 6, k + 4, 5);
        world.setBlock(i + 0, j + 6, k + 3, 5);
        world.setBlock(i + 0, j + 6, k + 2, 5);
        world.setBlock(i + 0, j + 6, k + 1, 5);
        world.setBlock(i + 0, j + 6, k + 0, 53);
        world.setBlock(i + 1, j + 6, k + 6, 53);
        world.setBlock(i + 1, j + 6, k + 0, 53);
        world.setBlock(i + 2, j + 6, k + 6, 53);
        world.setBlock(i + 2, j + 6, k + 0, 53);
        world.setBlock(i + 3, j + 6, k + 6, 53);
        world.setBlock(i + 3, j + 6, k + 0, 53);
        world.setBlock(i + 4, j + 6, k + 6, 53);
        world.setBlock(i + 4, j + 6, k + 0, 53);
        world.setBlock(i + 5, j + 6, k + 6, 53);
        world.setBlock(i + 5, j + 6, k + 0, 53);
        world.setBlock(i + 6, j + 6, k + 6, 53);
        world.setBlock(i + 6, j + 6, k + 0, 53);
        world.setBlock(i + 7, j + 6, k + 6, 53);
        world.setBlock(i + 7, j + 6, k + 0, 53);
        world.setBlock(i + 8, j + 6, k + 6, 53);
        world.setBlock(i + 8, j + 6, k + 0, 53);
        world.setBlock(i + 9, j + 6, k + 6, 53);
        world.setBlock(i + 9, j + 6, k + 5, 5);
        world.setBlock(i + 9, j + 6, k + 4, 5);
        world.setBlock(i + 9, j + 6, k + 3, 5);
        world.setBlock(i + 9, j + 6, k + 2, 5);
        world.setBlock(i + 9, j + 6, k + 1, 5);
        world.setBlock(i + 9, j + 6, k + 0, 53);
        world.setBlock(i + 0, j + 7, k + 5, 53);
        world.setBlock(i + 0, j + 7, k + 4, 5);
        world.setBlock(i + 0, j + 7, k + 3, 5);
        world.setBlock(i + 0, j + 7, k + 2, 5);
        world.setBlock(i + 0, j + 7, k + 1, 53);
        world.setBlock(i + 1, j + 7, k + 5, 53);
        world.setBlock(i + 1, j + 7, k + 3, 50);
        world.setBlock(i + 1, j + 7, k + 1, 53);
        world.setBlock(i + 2, j + 7, k + 5, 53);
        world.setBlock(i + 2, j + 7, k + 1, 53);
        world.setBlock(i + 3, j + 7, k + 5, 53);
        world.setBlock(i + 3, j + 7, k + 1, 53);
        world.setBlock(i + 4, j + 7, k + 5, 53);
        world.setBlock(i + 4, j + 7, k + 1, 53);
        world.setBlock(i + 5, j + 7, k + 5, 53);
        world.setBlock(i + 5, j + 7, k + 1, 53);
        world.setBlock(i + 6, j + 7, k + 5, 53);
        world.setBlock(i + 6, j + 7, k + 1, 53);
        world.setBlock(i + 7, j + 7, k + 5, 53);
        world.setBlock(i + 7, j + 7, k + 1, 53);
        world.setBlock(i + 8, j + 7, k + 5, 53);
        world.setBlock(i + 8, j + 7, k + 3, 50);
        world.setBlock(i + 8, j + 7, k + 1, 53);
        world.setBlock(i + 9, j + 7, k + 5, 53);
        world.setBlock(i + 9, j + 7, k + 4, 5);
        world.setBlock(i + 9, j + 7, k + 3, 5);
        world.setBlock(i + 9, j + 7, k + 2, 5);
        world.setBlock(i + 9, j + 7, k + 1, 53);
        world.setBlock(i + 0, j + 8, k + 4, 53);
        world.setBlock(i + 0, j + 8, k + 3, 5);
        world.setBlock(i + 0, j + 8, k + 2, 53);
        world.setBlock(i + 1, j + 8, k + 4, 53);
        world.setBlock(i + 1, j + 8, k + 3, 5);
        world.setBlock(i + 1, j + 8, k + 2, 53);
        world.setBlock(i + 2, j + 8, k + 4, 53);
        world.setBlock(i + 2, j + 8, k + 3, 5);
        world.setBlock(i + 2, j + 8, k + 2, 53);
        world.setBlock(i + 3, j + 8, k + 4, 53);
        world.setBlock(i + 3, j + 8, k + 3, 5);
        world.setBlock(i + 3, j + 8, k + 2, 53);
        world.setBlock(i + 4, j + 8, k + 4, 53);
        world.setBlock(i + 4, j + 8, k + 3, 5);
        world.setBlock(i + 4, j + 8, k + 2, 53);
        world.setBlock(i + 5, j + 8, k + 4, 53);
        world.setBlock(i + 5, j + 8, k + 3, 5);
        world.setBlock(i + 5, j + 8, k + 2, 53);
        world.setBlock(i + 6, j + 8, k + 4, 53);
        world.setBlock(i + 6, j + 8, k + 3, 5);
        world.setBlock(i + 6, j + 8, k + 2, 53);
        world.setBlock(i + 7, j + 8, k + 4, 53);
        world.setBlock(i + 7, j + 8, k + 3, 5);
        world.setBlock(i + 7, j + 8, k + 2, 53);
        world.setBlock(i + 8, j + 8, k + 4, 53);
        world.setBlock(i + 8, j + 8, k + 3, 5);
        world.setBlock(i + 8, j + 8, k + 2, 53);
        world.setBlock(i + 9, j + 8, k + 4, 53);
        world.setBlock(i + 9, j + 8, k + 3, 5);
        
        EntityLiving entity = new EntityGuildMaster(world);
        entity.setPosition(i + 2.5D, j + 2.0D, k + 3.0D);
        world.spawnEntityInWorld(entity);
        
        return world.setBlock(i + 9, j + 8, k + 2, 53);
	}
}
